Workbook

Sheet FUO
A1: CAJIGA — FACTORES DE UTILIDAD (FUO)
A2: El FUO multiplica el costo del componente para obtener el precio de venta. Edita solo las celdas azules.
A4: NIVEL | B4: NOMBRE | C4: FACTOR FUO | D4: DESCRIPCIÓN / CUÁNDO USARLO | E4: IVA APLICADO
A5: FUO 1.15 | B5: ECONÓMICO | C5: 1.15 | D5: Proyectos muy básicos: melamina sencilla, sin herrajes especiales, sin acabados. | E5: 1.16
A6: FUO 1.25 | B6: BÁSICO | C6: 1.25 | D6: Proyectos sencillos: melamina con chapa, herrajes estándar, diseño básico. | E6: 1.16
A7: FUO 1.32 | B7: BÁSICO+ | C7: 1.32 | D7: Proyectos sencillos con mejor acabado: MDF lacado, herrajes estándar, diseño semi-personalizado. | E7: 1.16
A8: FUO 1.40 | B8: ESTÁNDAR | C8: 1.4 | D8: Proyectos intermedios: MDF lacado, herrajes de calidad media, diseño personalizado. | E8: 1.16
A9: FUO 1.48 | B9: ESTÁNDAR+ | C9: 1.48 | D9: Proyectos intermedios-altos: MDF + madera maciza combinada, herrajes soft-close, iluminación básica. | E9: 1.16
A10: FUO 1.55 | B10: PREMIUM | C10: 1.55 | D10: Proyectos de alta gama: madera maciza, herrajes premium, iluminación LED, diseño exclusivo. | E10: 1.16
A11: FUO 1.65 | B11: PREMIUM+ | C11: 1.65 | D11: Proyectos de lujo: maderas finas (nogal/encino), herrajes de alta gama, iluminación completa. | E11: 1.16
A12: FUO 1.75 | B12: LUJO | C12: 1.75 | D12: Proyectos de lujo completo: maderas selectas, herrajes europeos, domótica básica, diseño a medida. | E12: 1.16
A13: FUO 1.88 | B13: LUJO+ | C13: 1.88 | D13: Proyectos exclusivos: maderas importadas, herrajes de diseñador, domótica, acabados artesanales. | E13: 1.16
A14: FUO 2.00 | B14: ULTRA PREMIUM | C14: 2 | D14: Proyectos ultra exclusivos: materiales importados, diseño de autor, instalación especial, garantía extendida. | E14: 1.16
A16: ℹ️ El factor FUO incluye: costo de fabricación + mano de obra + gastos indirectos + utilidad. El IVA se aplica sobre el precio de venta al momento de facturar.

Sheet INSUMOS
A1: FÁBRICA CAJIGA — CATÁLOGO MAESTRO DE INSUMOS
A2: 368 insumos • 12 líneas • Precios en MXN • Actualizar precios en azul • Clave original conservada para cruce
A3: TIPO DE CAMBIO USD/MXN | C3: 21.08 | D3: ← Actualizar mensualmente
A5: LÍNEA | B5: SUBLÍNEA | C5: CLAVE | D5: CLAVE ORIG. | E5: DESCRIPCIÓN | F5: UNIDAD | G5: PRECIO USD | H5: PRECIO MXN | I5: MERMA % | J5: COSTO EFECT. | K5: USO | L5: NOTAS
A6: 🎨 BARNIZ (19 items)
A7: BARNIZ | B7: ACEITE | C7: BAR-ACE-002 | D7: MYRV048 | E7: ACEITE IMPREGNANTE CHOCOLATE HI-0129.40 | F7: LT | G7: =IF(H7="","",ROUND(H7/$C$3,2)) -> 7.84 | H7: 165.2 | J7: =IF(H7="","",ROUND(H7*(1+IF(I7="",0,I7)),2)) -> 165.2 | K7: 1
A8: BARNIZ | B8: ACEITE | C8: BAR-ACE-001 | D8: MYRV047 | E8: ACEITE IMPREGNANTE NOGALCLASICO HI-0115.40 | F8: LT | G8: =IF(H8="","",ROUND(H8/$C$3,2)) -> 7.84 | H8: 165.2 | J8: =IF(H8="","",ROUND(H8*(1+IF(I8="",0,I8)),2)) -> 165.2 | K8: 1
A9: BARNIZ | B9: ACEITE | C9: BAR-ACE-003 | D9: MYRV049 | E9: PROTECTOLACK TRANSPARENTE 20UB MATE HI-0600.40 | F9: LT | G9: =IF(H9="","",ROUND(H9/$C$3,2)) -> 7.84 | H9: 165.2 | J9: =IF(H9="","",ROUND(H9*(1+IF(I9="",0,I9)),2)) -> 165.2 | K9: 1 | L9: Fb:0.4 | $66.08
A10: BARNIZ | B10: FONDO | C10: BAR-FON-002 | D10: BFON011 | E10: FONDO POLIACRILICO | F10: LT MEZCLA | G10: =IF(H10="","",ROUND(H10/$C$3,2)) -> 8.85 | H10: 186.56 | J10: =IF(H10="","",ROUND(H10*(1+IF(I10="",0,I10)),2)) -> 186.56 | K10: 1 | L10: Fb:0.6 | $111.94
A11: BARNIZ | B11: FONDO | C11: BAR-FON-001 | D11: BFON010 | E11: FONDO POLIURETANO | F11: LT MEZCLA | G11: =IF(H11="","",ROUND(H11/$C$3,2)) -> 4.47 | H11: 94.27 | J11: =IF(H11="","",ROUND(H11*(1+IF(I11="",0,I11)),2)) -> 94.27 | K11: 1 | L11: Fb:0.44 | $41.48
A12: BARNIZ | B12: HIDROLACA | C12: BAR-HID-001 | D12: BLAC066 | E12: HIDROLACA | F12: LT MEZCLA | G12: =IF(H12="","",ROUND(H12/$C$3,2)) -> 4.87 | H12: 102.7 | J12: =IF(H12="","",ROUND(H12*(1+IF(I12="",0,I12)),2)) -> 102.7 | K12: 1
A13: BARNIZ | B13: LACA | C13: BAR-LAC-005 | D13: BLAC069 | E13: AUTOLACK MEZCLA DE COLORES BROCHA | F13: LT MEZCLA | G13: =IF(H13="","",ROUND(H13/$C$3,2)) -> 4.83 | H13: 101.77 | J13: =IF(H13="","",ROUND(H13*(1+IF(I13="",0,I13)),2)) -> 101.77 | K13: 1 | L13: Fb:0.37 | $37.65
A14: BARNIZ | B14: LACA | C14: BAR-LAC-004 | D14: BLAC067 | E14: AUTOLACK MEZCLA DE COLORES PISTOLA | F14: LT MEZCLA | G14: =IF(H14="","",ROUND(H14/$C$3,2)) -> 4.83 | H14: 101.77 | J14: =IF(H14="","",ROUND(H14*(1+IF(I14="",0,I14)),2)) -> 101.77 | K14: 1 | L14: Fb:0.93 | $94.65
A15: BARNIZ | B15: LACA | C15: BAR-LAC-003 | D15: BLAC064 | E15: BICAPA | F15: LT MEZCLA | G15: =IF(H15="","",ROUND(H15/$C$3,2)) -> 8.13 | H15: 171.47 | J15: =IF(H15="","",ROUND(H15*(1+IF(I15="",0,I15)),2)) -> 171.47 | K15: 1 | L15: Fb:0.4 | $68.59
A16: BARNIZ | B16: LACA | C16: BAR-LAC-001 | D16: BLAC062 | E16: LACA ACRILICA | F16: LT MEZCLA | G16: =IF(H16="","",ROUND(H16/$C$3,2)) -> 4.58 | H16: 96.6 | J16: =IF(H16="","",ROUND(H16*(1+IF(I16="",0,I16)),2)) -> 96.6 | K16: 1 | L16: Fb:0.93 | $89.84
A17: BARNIZ | B17: LACA | C17: BAR-LAC-002 | D17: BLAC063 | E17: LACA MATE | F17: LT MEZCLA | G17: =IF(H17="","",ROUND(H17/$C$3,2)) -> 3.49 | H17: 73.49 | J17: =IF(H17="","",ROUND(H17*(1+IF(I17="",0,I17)),2)) -> 73.49 | K17: 1 | L17: Fb:0.93 | $68.35
A18: BARNIZ | B18: POLYLACK | C18: BAR-PLK-001 | D18: BLAC065 | E18: POLYLACK ( PAROTAS ) | F18: LT MEZCLA | G18: =IF(H18="","",ROUND(H18/$C$3,2)) -> 6.15 | H18: 129.71 | J18: =IF(H18="","",ROUND(H18*(1+IF(I18="",0,I18)),2)) -> 129.71 | K18: 1 | L18: Fb:0.36 | $46.70
A19: BARNIZ | B19: TINTA | C19: BAR-TIN-005 | D19: BTIN70 | E19: BONA NATURE | F19: LT MEZCLA | G19: =IF(H19="","",ROUND(H19/$C$3,2)) -> 47.74 | H19: 1006.28 | J19: =IF(H19="","",ROUND(H19*(1+IF(I19="",0,I19)),2)) -> 1006.28 | K19: 1
A20: BARNIZ | B20: TINTA | C20: BAR-TIN-001 | D20: BTIN033 | E20: TINTA TONO 1/ TZALAM COLOR (ALCOHOL) | F20: LT MEZCLA | G20: =IF(H20="","",ROUND(H20/$C$3,2)) -> 1.56 | H20: 32.94 | J20: =IF(H20="","",ROUND(H20*(1+IF(I20="",0,I20)),2)) -> 32.94 | K20: 1 | L20: Fb:0.37 | $12.19
A21: BARNIZ | B21: TINTA | C21: BAR-TIN-002 | D21: BTIN034 | E21: TINTA TONO NOGAL COLOR | F21: LT MEZCLA | G21: =IF(H21="","",ROUND(H21/$C$3,2)) -> 2.67 | H21: 56.34 | J21: =IF(H21="","",ROUND(H21*(1+IF(I21="",0,I21)),2)) -> 56.34 | K21: 1 | L21: Fb:0.37 | $20.85
A22: BARNIZ | B22: TINTA | C22: BAR-TIN-003 | D22: BTIN035 | E22: TINTA TONO 1/ TZALAM FONDO (ACEITE) | F22: LT MEZCLA | G22: =IF(H22="","",ROUND(H22/$C$3,2)) -> 1.7 | H22: 35.79 | J22: =IF(H22="","",ROUND(H22*(1+IF(I22="",0,I22)),2)) -> 35.79 | K22: 1 | L22: Fb:0.37 | $13.24
A23: BARNIZ | B23: TINTA | C23: BAR-TIN-004 | D23: BTIN036 | E23: TINTA TONO NOGAL FONDO | F23: LT MEZCLA | G23: =IF(H23="","",ROUND(H23/$C$3,2)) -> 1.7 | H23: 35.8 | J23: =IF(H23="","",ROUND(H23*(1+IF(I23="",0,I23)),2)) -> 35.8 | K23: 1 | L23: Fb:0.37 | $13.25
A24: BARNIZ | B24: VARIOS | C24: BAR-VAR-001 | D24: SOL001 | E24: THINNER AMERICANO | F24: LT | G24: =IF(H24="","",ROUND(H24/$C$3,2)) -> 2.41 | H24: 50.9 | J24: =IF(H24="","",ROUND(H24*(1+IF(I24="",0,I24)),2)) -> 50.9 | K24: 1
A25: BARNIZ | B25: VARIOS | C25: BAR-VAR-002 | D25: SOL002 | E25: THINNER ESTANDAR | F25: LT | G25: =IF(H25="","",ROUND(H25/$C$3,2)) -> 1.68 | H25: 35.4 | J25: =IF(H25="","",ROUND(H25*(1+IF(I25="",0,I25)),2)) -> 35.4 | K25: 1
A27: 🪵 MADERA (45 items)
A28: MADERA | B28: CHAPA | C28: MAD-CHP-001 | D28: ACHA048 | E28: CHAPA ENCINO ROJO | F28: M2 | G28: =IF(H28="","",ROUND(H28/$C$3,2)) -> 2.18 | H28: 46 | J28: =IF(H28="","",ROUND(H28*(1+IF(I28="",0,I28)),2)) -> 46 | K28: 1
A29: MADERA | B29: CHAPA | C29: MAD-CHP-005 | D29: ACHA052 | E29: CHAPA HUANACAXTLE | F29: M2 | G29: =IF(H29="","",ROUND(H29/$C$3,2)) -> 3.44 | H29: 72.41 | J29: =IF(H29="","",ROUND(H29*(1+IF(I29="",0,I29)),2)) -> 72.41 | K29: 1
A30: MADERA | B30: CHAPA | C30: MAD-CHP-002 | D30: ACHA049 | E30: CHAPA NOGAL NATURAL | F30: M2 | G30: =IF(H30="","",ROUND(H30/$C$3,2)) -> 4.36 | H30: 92 | J30: =IF(H30="","",ROUND(H30*(1+IF(I30="",0,I30)),2)) -> 92 | K30: 1
A31: MADERA | B31: CHAPA | C31: MAD-CHP-003 | D31: ACHA050 | E31: CHAPA OKUME T.A. X 2.50 | F31: M2 | G31: =IF(H31="","",ROUND(H31/$C$3,2)) -> 2 | H31: 42.2413 | J31: =IF(H31="","",ROUND(H31*(1+IF(I31="",0,I31)),2)) -> 42.24 | K31: 1
A32: MADERA | B32: CHAPA | C32: MAD-CHP-004 | D32: ACHA051 | E32: CHAPA TZALAM | F32: M2 | G32: =IF(H32="","",ROUND(H32/$C$3,2)) -> 3.6 | H32: 75.8621 | J32: =IF(H32="","",ROUND(H32*(1+IF(I32="",0,I32)),2)) -> 75.86 | K32: 1
A33: MADERA | B33: GUALDRA | C33: MAD-GUA-001 | D33: AMAG006 | E33: TABLA DE LA GUALDRA | F33: PIE | G33: =IF(H33="","",ROUND(H33/$C$3,2)) -> 0.95 | H33: 20 | J33: =IF(H33="","",ROUND(H33*(1+IF(I33="",0,I33)),2)) -> 20 | K33: 2
A34: MADERA | B34: MADERA | C34: MAD-MAC-004 | D34: AMAA004 | E34: MADERA POPLAR ESFUTADO (ALAMO )1" 4/4 1COMUN | F34: PIE | G34: =IF(H34="","",ROUND(H34/$C$3,2)) -> 1.1 | H34: 23.188 | J34: =IF(H34="","",ROUND(H34*(1+IF(I34="",0,I34)),2)) -> 23.19 | K34: 1
A35: MADERA | B35: MADERA | C35: MAD-MAC-003 | D35: AMAA001 | E35: MADERA POPLAR ESFUTADO (ALAMO )1" 4/4 2C | F35: PIE | G35: =IF(H35="","",ROUND(H35/$C$3,2)) -> 1.59 | H35: 33.5172 | J35: =IF(H35="","",ROUND(H35*(1+IF(I35="",0,I35)),2)) -> 33.52 | K35: 1
A36: MADERA | B36: MADERA | C36: MAD-MAC-005 | D36: AMAA002 | E36: MADERA DE ALAMO 1 1/2" 6/4 1COMUN | F36: PIE | G36: =IF(H36="","",ROUND(H36/$C$3,2)) -> 1.43 | H36: 30.1444 | J36: =IF(H36="","",ROUND(H36*(1+IF(I36="",0,I36)),2)) -> 30.14 | K36: 2
A37: MADERA | B37: MADERA | C37: MAD-MAC-001 | D37: AMAE001 | E37: MADERA DE ENCINO ROJO FAS 4/4" 1" | F37: PIE | G37: =IF(H37="","",ROUND(H37/$C$3,2)) -> 2.09 | H37: 44 | J37: =IF(H37="","",ROUND(H37*(1+IF(I37="",0,I37)),2)) -> 44 | K37: 1
A38: MADERA | B38: MADERA | C38: MAD-MAC-002 | D38: AMAE002 | E38: MADERA DE ENCINO ROJO FAS 6/4" 1 1/2" | F38: PIE | G38: =IF(H38="","",ROUND(H38/$C$3,2)) -> 4.22 | H38: 89 | J38: =IF(H38="","",ROUND(H38*(1+IF(I38="",0,I38)),2)) -> 89 | K38: 1
A39: MADERA | B39: MADERA | C39: MAD-MAC-012 | D39: AMAH001 | E39: MADERA HUACASTLE 1" | F39: PIE | G39: =IF(H39="","",ROUND(H39/$C$3,2)) -> 2.61 | H39: 55 | J39: =IF(H39="","",ROUND(H39*(1+IF(I39="",0,I39)),2)) -> 55 | K39: 2
... A72: MADERA | B72: TRIPLAY | C72: MAD-TRI-001 | D72: ATRT001 | E72: TRIPLAY TZALAM 6mm 244L | F72: PZA | G72: =IF(H72="","",ROUND(H72/$C$3,2)) -> 45 | H72: 948.6 | J72: =IF(H72="","",ROUND(H72*(1+IF(I72="",0,I72)),2)) -> 948.6 | K72: 1
A74: 🔩 HERRAJE (46 items)
A75: HERRAJE | B75: BISAGRA | C75: HER-BIS-001 | D75: MYRV584 | E75: BISAGRA ACERO INOX 3" X 3" | F75: PZA | G75: =IF(H75="","",ROUND(H75/$C$3,2)) -> 2.86 | H75: 60.39 | J75: =IF(H75="","",ROUND(H75*(1+IF(I75="",0,I75)),2)) -> 60.39 | K75: 1
...

Sheet COSTOS_M2
A1: CAJIGA — COSTO DE MATERIAL + CONSUMIBLES POR M²
A2: Incluye triplay + chapa + madera maciza + MDF + consumibles de barniz (fondo, laca, tinta). Datos extraídos de la tabla de componentes real.
A4: COMPONENTE | B4: TAMAÑO | C4: M² HASTA | D4: HUANACAXTLE $/m² | E4: ENCINO $/m² | F4: NOGAL $/m² | G4: CONSUMIBLES $/m² | H4: CLAVE
A5: PARAL 1 VISTA | B5: CHICO | C5: 0.5 | D5: 522 | E5: 472 | F5: 495 | G5: 174 | H5: PARAL 1 VISTA|CHICO
A6: PARAL 1 VISTA | B6: MEDIANO | C6: 1 | D6: 583 | E6: 532 | F6: 552 | G6: 176 | H6: PARAL 1 VISTA|MEDIANO
A7: PARAL 1 VISTA | B7: GRANDE | C7: 99 | D7: 559 | E7: 511 | F7: 527 | G7: 162 | H7: PARAL 1 VISTA|GRANDE
A8: PARAL 2 VISTAS | B8: CHICO | C8: 0.5 | D8: 871 | E8: 773 | F8: 807 | G8: 339 | H8: PARAL 2 VISTAS|CHICO
A9: PARAL 2 VISTAS | B9: MEDIANO | C9: 1 | D9: 978 | E9: 873 | F9: 905 | G9: 343 | H9: PARAL 2 VISTAS|MEDIANO
A10: PARAL 2 VISTAS | B10: GRANDE | C10: 99 | D10: 883 | E10: 791 | F10: 817 | G10: 316 | H10: PARAL 2 VISTAS|GRANDE
A11: PISO | B11: CHICO | C11: 0.5 | D11: 531 | E11: 485 | F11: 501 | G11: 174 | H11: PISO|CHICO
A12: PISO | B12: MEDIANO | C12: 1 | D12: 494 | E12: 448 | F12: 462 | G12: 176 | H12: PISO|MEDIANO
A13: PISO | B13: GRANDE | C13: 99 | D13: 482 | E13: 438 | F13: 450 | G13: 162 | H13: PISO|GRANDE
A14: PISO CON ZOCLO | B14: CHICO | C14: 0.5 | D14: 584 | E14: 534 | F14: 551 | G14: 191 | H14: PISO CON ZOCLO|CHICO
A15: PISO CON ZOCLO | B15: MEDIANO | C15: 1 | D15: 543 | E15: 493 | F15: 508 | G15: 194 | H15: PISO CON ZOCLO|MEDIANO
A16: PISO CON ZOCLO | B16: GRANDE | C16: 99 | D16: 530 | E16: 482 | F16: 495 | G16: 178 | H16: PISO CON ZOCLO|GRANDE
... A40: TUBO COLGAR | B40: GRANDE | C40: 99 | D40: 66 | E40: 66 | F40: 66 | G40: 0 | H40: TUBO COLGAR|GRANDE
A41: ZAPATERA EXTRAÍBLE | B41: CHICO | C41: 0.5 | D41: 367 | E41: 329 | F41: 408 | G41: 213 | H41: =A41&"|"&B41 -> ZAPATERA EXTRAÍBLE|CHICO
A42: ZAPATERA EXTRAÍBLE | B42: MEDIANO | C42: 1 | D42: 344 | E42: 310 | F42: 384 | G42: 198 | H42: =A42&"|"&B42 -> ZAPATERA EXTRAÍBLE|MEDIANO
A43: ZAPATERA EXTRAÍBLE | B43: GRANDE | C43: 99 | D43: 317 | E43: 285 | F43: 354 | G43: 181 | H43: =A43&"|"&B43 -> ZAPATERA EXTRAÍBLE|GRANDE
A44: PARAL DELGADO 2V | B44: CHICO | C44: 0.5 | D44: 575 | E44: 435 | F44: 535 | G44: 300 | H44: =A44&"|"&B44 -> PARAL DELGADO 2V|CHICO
A45: PARAL DELGADO 2V | B45: MEDIANO | C45: 1 | D45: 540 | E45: 400 | F45: 500 | G45: 285 | H45: =A45&"|"&B45 -> PARAL DELGADO 2V|MEDIANO
A46: PARAL DELGADO 2V | B46: GRANDE | C46: 99 | D46: 520 | E46: 385 | F46: 480 | G46: 265 | H46: =A46&"|"&B46 -> PARAL DELGADO 2V|GRANDE
A47: ENTREPAÑO DELGADO | B47: CHICO | C47: 0.5 | D47: 575 | E47: 435 | F47: 535 | G47: 300 | H47: =A47&"|"&B47 -> ENTREPAÑO DELGADO|CHICO
A48: ENTREPAÑO DELGADO | B48: MEDIANO | C48: 1 | D48: 540 | E48: 400 | F48: 500 | G48: 285 | H48: =A48&"|"&B48 -> ENTREPAÑO DELGADO|MEDIANO
A49: ENTREPAÑO DELGADO | B49: GRANDE | C49: 99 | D49: 520 | E49: 385 | F49: 480 | G49: 265 | H49: =A49&"|"&B49 -> ENTREPAÑO DELGADO|GRANDE
A50: ESPEJO | B50: CHICO | C50: 0.5 | D50: 520 | E50: 520 | F50: 520 | G50: 0 | H50: =A50&"|"&B50 -> ESPEJO|CHICO
A51: ESPEJO | B51: MEDIANO | C51: 1 | D51: 480 | E51: 480 | F51: 480 | G51: 0 | H51: =A51&"|"&B51 -> ESPEJO|MEDIANO
A52: ESPEJO | B52: GRANDE | C52: 99 | D52: 470 | E52: 470 | F52: 470 | G52: 0 | H52: =A52&"|"&B52 -> ESPEJO|GRANDE
... A67: FONDO MADERA | B67: GRANDE | C67: 99 | D67: 160 | E67: 120 | F67: 135 | G67: 100 | H67: =A67&"|"&B67 -> FONDO MADERA|GRANDE
A69: FACTOR ESPECIAL | B69: FACTOR | C69: APLICA CUANDO
A70: ANCHO ESPECIAL | B70: 1.3 | C70: Ancho > 70 cm
A71: LARGO/ALTO ESPECIAL | B71: 1.3 | C71: Largo/Alto > 244 cm

Sheet MANO_DE_OBRA
A1: y
A2: Ingresa las HORAS (o minutos para CNC) que tarda cada área por componente. El costo se calcula automáticamente.
A4: PRECIO / HORA (O MINUTO) POR ÁREA
A5: HABILIT. | B5: CNC (min) | C5: ARMADO GRAL | D5: CHAPA | E5: PULIDO | F5: ENTINTADO | G5: FONDO | H5: PUL. FONDO | I5: PREPARADO | J5: BARNIZ COL. | K5: INST. ARMAD | L5: INST. BARN
A6: 134.7 | B6: 4.45 | C6: 134.7 | D6: 135.75 | E6: 127.65 | F6: 136.89 | G6: 136.89 | H6: 127.65 | I6: 136.89 | J6: 136.89 | K6: 134.7 | L6: 136.89
A8: HORAS POR COMPONENTE Y TAMAÑO (ingresa horas; para CNC ingresa minutos)
A9: COMPONENTE | B9: TAMAÑO | C9: M² HASTA | D9: HABILIT. | E9: CNC (min) | F9: ARM.GRAL | G9: CHAPA | H9: PULIDO | I9: ENTINT. | J9: FONDO | K9: PUL.FON | L9: PREPAR. | M9: BARNIZ | N9: I.ARMAD | O9: I.BARN | P9: COSTO MO | Q9: CLAVE
A10: PARAL 1 VISTA | B10: CHICO | C10: 0.5 | D10: 0.2 | E10: 0 | F10: 0.3 | G10: 0.166 | H10: 0.104 | I10: 0.104 | J10: 0.104 | K10: 0.1048 | L10: 0.104 | M10: 0.4 | N10: 1.5 | O10: 0.25 | P10: =D10*$A$6+E10*$B$6+F10*$C$6+G10*$D$6+H10*$E$6+I10*$F$6+J10*$G$6+K10*$H$6+L10*$I$6+M10*$J$6+N10*$K$6+O10*$L$6 -> 450.276 | Q10: =A10&"|"&B10 -> PARAL 1 VISTA|CHICO
A11: PARAL 1 VISTA | B11: MEDIANO | C11: 1 | D11: 0.2 | E11: 0 | F11: 0.4 | G11: 0.166 | H11: 0.176 | I11: 0.176 | J11: 0.176 | K11: 0.1772 | L11: 0.176 | M11: 0.4 | N11: 1.5 | O11: 0.25 | P11: =D11*$A$6+E11*$B$6+F11*$C$6+G11*$D$6+H11*$E$6+I11*$F$6+J11*$G$6+K11*$H$6+L11*$I$6+M11*$J$6+N11*$K$6+O11*$L$6 -> 511.7469 | Q11: =A11&"|"&B11 -> PARAL 1 VISTA|MEDIANO
A12: PARAL 1 VISTA | B12: GRANDE | C12: 99 | D12: 0.2 | E12: 0 | F12: 0.467 | G12: 0.166 | H12: 0.288 | I12: 0.288 | J12: 0.288 | K12: 0.2255 | L12: 0.288 | M12: 0.4 | N12: 1.5 | O12: 0.25 | P12: =D12*$A$6+E12*$B$6+F12*$C$6+G12*$D$6+H12*$E$6+I12*$F$6+J12*$G$6+K12*$H$6+L12*$I$6+M12*$J$6+N12*$K$6+O12*$L$6 -> 587.22913 | Q12: =A12&"|"&B12 -> PARAL 1 VISTA|GRANDE
A13: PARAL 2 VISTAS | B13: CHICO | C13: 0.5 | D13: 0.2 | E13: 0 | F13: 0.5 | G13: 0.166 | H13: 0.201 | I13: 0.201 | J13: 0.201 | K13: 0.2014 | L13: 0.201 | M13: 0.5 | N13: 1 | O13: 0.25 | P13: =D13*$A$6+E13*$B$6+F13*$C$6+G13*$D$6+H13*$E$6+I13*$F$6+J13*$G$6+K13*$H$6+L13*$I$6+M13*$J$6+N13*$K$6+O13*$L$6 -> 488.10303 | Q13: =A13&"|"&B13 -> PARAL 2 VISTAS|CHICO
A14: PARAL 2 VISTAS | B14: MEDIANO | C14: 1 | D14: 0.2 | E14: 0 | F14: 0.625 | G14: 0.166 | H14: 0.356 | I14: 0.356 | J14: 0.356 | K14: 0.3558 | L14: 0.356 | M14: 0.5 | N14: 1 | O14: 0.25 | P14: =D14*$A$6+E14*$B$6+F14*$C$6+G14*$D$6+H14*$E$6+I14*$F$6+J14*$G$6+K14*$H$6+L14*$I$6+M14*$J$6+N14*$K$6+O14*$L$6 -> 608.08929 | Q14: =A14&"|"&B14 -> PARAL 2 VISTAS|MEDIANO
A15: PARAL 2 VISTAS | B15: GRANDE | C15: 99 | D15: 0.2 | E15: 0 | F15: 0.708 | G15: 0.166 | H15: 0.554 | I15: 0.554 | J15: 0.554 | K15: 0.554 | L15: 0.554 | M15: 0.5 | N15: 1 | O15: 0.25 | P15: =D15*$A$6+E15*$B$6+F15*$C$6+G15*$D$6+H15*$E$6+I15*$F$6+J15*$G$6+K15*$H$6+L15*$I$6+M15*$J$6+N15*$K$6+O15*$L$6 -> 751.15698 | Q15: =A15&"|"&B15 -> PARAL 2 VISTAS|GRANDE
A16: PISO | B16: CHICO | C16: 0.5 | D16: 0.2 | E16: 0 | F16: 0.5 | G16: 0.166 | H16: 0.069 | I16: 0.069 | J16: 0.069 | K16: 0.069 | L16: 0.069 | M16: 0.25 | N16: 1 | O16: 0.2 | P16: =D16*$A$6+E16*$B$6+F16*$C$6+G16*$D$6+H16*$E$6+I16*$F$6+J16*$G$6+K16*$H$6+L16*$I$6+M16*$J$6+N16*$K$6+O16*$L$6 -> 359.07693 | Q16: =A16&"|"&B16 -> PISO|CHICO
A17: PISO | B17: MEDIANO | C17: 1 | D17: 0.2 | E17: 0 | F17: 0.533 | G17: 0.171 | H17: 0.147 | I17: 0.147 | J17: 0.147 | K17: 0.1457 | L17: 0.147 | M17: 0.33 | N17: 1 | O17: 0.2 | P17: =D17*$A$6+E17*$B$6+F17*$C$6+G17*$D$6+H17*$E$6+I17*$F$6+J17*$G$6+K17*$H$6+L17*$I$6+M17*$J$6+N17*$K$6+O17*$L$6 -> 426.93169 | Q17: =A17&"|"&B17 -> PISO|MEDIANO
A18: PISO | B18: GRANDE | C18: 99 | D18: 0.3 | E18: 0 | F18: 0.7 | G18: 0.2 | H18: 0.27 | I18: 0.27 | J18: 0.27 | K18: 0.2698 | L18: 0.27 | M18: 0.4 | N18: 1 | O18: 0.2 | P18: =D18*$A$6+E18*$B$6+F18*$C$6+G18*$D$6+H18*$E$6+I18*$F$6+J18*$G$6+K18*$H$6+L18*$I$6+M18*$J$6+N18*$K$6+O18*$L$6 -> 558.47037 | Q18: =A18&"|"&B18 -> PISO|GRANDE
A19: PISO CON ZOCLO | B19: CHICO | C19: 0.5 | D19: 0.22 | E19: 0 | F19: 0.55 | G19: 0.183 | H19: 0.076 | I19: 0.076 | J19: 0.076 | K19: 0.076 | L19: 0.076 | M19: 0.28 | N19: 1.1 | O19: 0.22 | P19: =D19*$A$6+E19*$B$6+F19*$C$6+G19*$D$6+H19*$E$6+I19*$F$6+J19*$G$6+K19*$H$6+L19*$I$6+M19*$J$6+N19*$K$6+O19*$L$6 -> 395.78997 | Q19: =A19&"|"&B19 -> PISO CON ZOCLO|CHICO
A20: PISO CON ZOCLO | B20: MEDIANO | C20: 1 | D20: 0.22 | E20: 0 | F20: 0.586 | G20: 0.188 | H20: 0.162 | I20: 0.162 | J20: 0.162 | K20: 0.16 | L20: 0.162 | M20: 0.36 | N20: 1.1 | O20: 0.22 | P20: =D20*$A$6+E20*$B$6+F20*$C$6+G20*$D$6+H20*$E$6+I20*$F$6+J20*$G$6+K20*$H$6+L20*$I$6+M20*$J$6+N20*$K$6+O20*$L$6 -> 469.28724 | Q20: =A20&"|"&B20 -> PISO CON ZOCLO|MEDIANO
A21: PISO CON ZOCLO | B21: GRANDE | C21: 99 | D21: 0.33 | E21: 0 | F21: 0.77 | G21: 0.22 | H21: 0.297 | I21: 0.297 | J21: 0.297 | K21: 0.297 | L21: 0.297 | M21: 0.44 | N21: 1.1 | O21: 0.22 | P21: =D21*$A$6+E21*$B$6+F21*$C$6+G21*$D$6+H21*$E$6+I21*$F$6+J21*$G$6+K21*$H$6+L21*$I$6+M21*$J$6+N21*$K$6+O21*$L$6 -> 614.34549 | Q21: =A21&"|"&B21 -> PISO CON ZOCLO|GRANDE
... A72: FONDO MADERA | B72: GRANDE | C72: 99 | D72: 0.15 | E72: 0 | F72: 0.2 | G72: 0 | H72: 0.25 | I72: 0.25 | J72: 0.25 | K72: 0.2 | L72: 0.25 | M72: 0.3 | N72: 0.2 | O72: 0.15 | P72: =D72*$A$6+E72*$B$6+F72*$C$6+G72*$D$6+H72*$E$6+I72*$F$6+J72*$G$6+K72*$H$6+L72*$I$6+M72*$J$6+N72*$K$6+O72*$L$6 -> 295.7955 | Q72: =A72&"|"&B72 -> FONDO MADERA|GRANDE
A74: ⚡ CHICO = hasta 0.50 m² | MEDIANO = 0.51 a 1.00 m² | GRANDE = más de 1.00 m². Puedes ajustar los límites en la columna "M² HASTA" (C). Ingresa HORAS en todas las áreas excepto CNC que es en MINUTOS.

Sheet HERRAJES
A1: CAJIGA — HERRAJES POR COMPONENTE
A2: Costo de herrajes asignado automáticamente al cotizar. Precios vinculados a INSUMOS.
A4: COMPONENTE | B4: PROFUNDIDAD | C4: CLAVE INSUMO | D4: DESCRIPCIÓN HERRAJE | E4: UNIDAD | F4: PRECIO UNIT. | G4: CANTIDAD | H4: COSTO HERRAJE | I4: NOTAS | J4: CLAVE LOOKUP
A5: CAJÓN | B5: 35 | C5: HER-COR-005 | D5: CORREDERA EXTENSIÓN TOTAL 35 CMS | E5: JGO | F5: 46.94 | G5: 1 | H5: =IF(F5=0,0,F5*G5) -> 46.94 | I5: 1 jgo por cajón | J5: CAJÓN|35
A6: CAJÓN | B6: 40 | C6: HER-COR-006 | D6: CORREDERA EXTENSIÓN TOTAL 40 CMS | E6: JGO | F6: 58.99 | G6: 1 | H6: =IF(F6=0,0,F6*G6) -> 58.99 | I6: 1 jgo por cajón | J6: CAJÓN|40
A7: CAJÓN | B7: 45 | C7: HER-COR-007 | D7: CORREDERA EXTENSIÓN TOTAL 45 CMS | E7: JGO | F7: 60.33 | G7: 1 | H7: =IF(F7=0,0,F7*G7) -> 60.33 | I7: 1 jgo por cajón | J7: CAJÓN|45
A8: CAJÓN | B8: 50 | C8: HER-COR-008 | D8: CORREDERA EXTENSIÓN TOTAL 50 CMS | E8: JGO | F8: 73.73 | G8: 1 | H8: =IF(F8=0,0,F8*G8) -> 73.73 | I8: 1 jgo por cajón | J8: CAJÓN|50
A9: CAJÓN | B9: 55 | C9: HER-COR-009 | D9: CORREDERA EXTENSIÓN TOTAL 55 CMS | E9: JGO | F9: 50.52 | G9: 1 | H9: =IF(F9=0,0,F9*G9) -> 50.52 | I9: 1 jgo por cajón | J9: CAJÓN|55
A10: CAJÓN | B10: 60 | C10: HER-COR-010 | D10: CORREDERA EXTENSIÓN TOTAL 60 CMS | E10: JGO | F10: 54.97 | G10: 1 | H10: =IF(F10=0,0,F10*G10) -> 54.97 | I10: 1 jgo por cajón | J10: CAJÓN|60
A11: PUERTA ABATIBLE | B11: TODAS | C11: HER-BIS-007 | D11: BISAGRA COBERTURA COMPLETA 30 mm | E11: PZA | F11: 60.57 | G11: 4 | H11: =IF(F11=0,0,F11*G11) -> 242.28 | I11: 4 bisagras por puerta | J11: PUERTA ABATIBLE|TODAS
A12: PUERTA ABATIBLE | B12: TODAS | C12: HER-CON-001 | D12: CONTRAS DE BISAGRAS | E12: PZA | F12: 17.28 | G12: 4 | H12: =IF(F12=0,0,F12*G12) -> 69.12 | I12: 4 contras por puerta | J12: PUERTA ABATIBLE|TODAS
A13: PUERTA CORREDERA | B13: TODAS | D13: SISTEMA RIEL INCLUIDO EN PRECIO BASE | F13: 0 | G13: 0 | H13: =IF(F13=0,0,F13*G13) -> 0 | I13: Sin herraje adicional | J13: PUERTA CORREDERA|TODAS
A14: PUERTA ESPEJO | B14: TODAS | C14: HER-BIS-007 | D14: BISAGRA COBERTURA COMPLETA 30 mm | E14: PZA | F14: 60.57 | G14: 4 | H14: =IF(F14=0,0,F14*G14) -> 242.28 | I14: 4 bisagras por puerta | J14: PUERTA ESPEJO|TODAS
A15: PUERTA ESPEJO | B15: TODAS | C15: HER-CON-001 | D15: CONTRAS DE BISAGRAS | E15: PZA | F15: 17.28 | G15: 4 | H15: =IF(F15=0,0,F15*G15) -> 69.12 | I15: 4 contras | J15: PUERTA ESPEJO|TODAS
A16: PUERTA ESPEJO | B16: TODAS | C16: ESP-ESP-001 | D16: ESPEJO FLOTADO CLARO 6 MM | E16: M2 | F16: 450.42 | H16: =IF(F16=0,0,F16*G16) -> 0 | I16: Cantidad = m² de puerta | J16: PUERTA ESPEJO|TODAS
A17: ENTREPAÑO LED | B17: TODAS | C17: ELE-TIR-001 | D17: TIRA LED HAFELE | E17: PZA | F17: 1008 | H17: =IF(F17=0,0,F17*G17) -> 0 | I17: Cant = ancho/100 (metros) | J17: ENTREPAÑO LED|TODAS
A18: TUBO COLGAR | B18: TODAS | C18: HER-TUB-001 | D18: TUBO OVAL 6 MTS | E18: PZA | F18: 331.04 | H18: =IF(F18=0,0,F18*G18) -> 0 | I18: Cant = largo/6 (fracción de tubo) | J18: TUBO COLGAR|TODAS
A19: TUBO COLGAR | B19: TODAS | C19: HER-BRI-001 | D19: BRIDA OVALADA CROMADA NÍQUEL | E19: PZA | F19: 1.37 | G19: 2 | H19: =IF(F19=0,0,F19*G19) -> 2.74 | I19: 2 bridas por tramo | J19: TUBO COLGAR|TODAS
A20: PARAL 1 VISTA | B20: TODAS | D20: SIN HERRAJE | F20: 0 | G20: 0 | H20: =IF(F20=0,0,F20*G20) -> 0 | J20: PARAL 1 VISTA|TODAS
A21: PARAL 2 VISTAS | B21: TODAS | D21: SIN HERRAJE | F21: 0 | G21: 0 | H21: =IF(F21=0,0,F21*G21) -> 0 | J21: PARAL 2 VISTAS|TODAS
A22: PISO | B22: TODAS | D22: SIN HERRAJE | F22: 0 | G22: 0 | H22: =IF(F22=0,0,F22*G22) -> 0 | J22: PISO|TODAS
A23: PISO CON ZOCLO | B23: TODAS | D23: SIN HERRAJE | F23: 0 | G23: 0 | H23: =IF(F23=0,0,F23*G23) -> 0 | J23: PISO CON ZOCLO|TODAS
A24: CIELO | B24: TODAS | D24: SIN HERRAJE | F24: 0 | G24: 0 | H24: =IF(F24=0,0,F24*G24) -> 0 | J24: CIELO|TODAS
A25: ENTREPAÑO | B25: TODAS | D25: SIN HERRAJE | F25: 0 | G25: 0 | H25: =IF(F25=0,0,F25*G25) -> 0 | J25: ENTREPAÑO|TODAS
A26: ZAPATERA EXTRAÍBLE | B26: 55 | C26: HER-COR-009 | D26: CORREDERA EXTENSIÓN TOTAL 55 CMS | E26: JGO | F26: 50.52 | G26: 1 | H26: =IF(F26=0,0,F26*G26) -> 50.52 | I26: 1 jgo por zapatera (prof 60cm) | J26: =A26&"|"&B26 -> ZAPATERA EXTRAÍBLE|55
A27: ZAPATERA EXTRAÍBLE | B27: 60 | C27: HER-COR-010 | D27: CORREDERA EXTENSIÓN TOTAL 60 CMS | E27: JGO | F27: 54.97 | G27: 1 | H27: =IF(F27=0,0,F27*G27) -> 54.97 | I27: 1 jgo por zapatera (prof 68cm) | J27: =A27&"|"&B27 -> ZAPATERA EXTRAÍBLE|60
A29: PARAL DELGADO 2V | B29: TODAS | D29: SIN HERRAJE | F29: 0 | G29: 0 | H29: =IF(F29=0,0,F29*G29) -> 0 | J29: =A29&"|"&B29 -> PARAL DELGADO 2V|TODAS
A30: ENTREPAÑO DELGADO | B30: TODAS | D30: SIN HERRAJE | F30: 0 | G30: 0 | H30: =IF(F30=0,0,F30*G30) -> 0 | J30: =A30&"|"&B30 -> ENTREPAÑO DELGADO|TODAS
A31: ESPEJO | B31: TODAS | D31: SIN HERRAJE | F31: 0 | G31: 0 | H31: =IF(F31=0,0,F31*G31) -> 0 | J31: =A31&"|"&B31 -> ESPEJO|TODAS
A32: MOLDURA SENCILLA | B32: TODAS | D32: SIN HERRAJE | F32: 0 | G32: 0 | H32: =IF(F32=0,0,F32*G32) -> 0 | J32: =A32&"|"&B32 -> MOLDURA SENCILLA|TODAS
A33: MOLDURA MEDIA | B33: TODAS | D33: SIN HERRAJE | F33: 0 | G33: 0 | H33: =IF(F33=0,0,F33*G33) -> 0 | J33: =A33&"|"&B33 -> MOLDURA MEDIA|TODAS
A34: MOLDURA DIFÍCIL | B34: TODAS | D34: SIN HERRAJE | F34: 0 | G34: 0 | H34: =IF(F34=0,0,F34*G34) -> 0 | J34: =A34&"|"&B34 -> MOLDURA DIFÍCIL|TODAS
A35: MOLDURA GRUESA DIFÍCIL | B35: TODAS | D35: SIN HERRAJE | F35: 0 | G35: 0 | H35: =IF(F35=0,0,F35*G35) -> 0 | J35: =A35&"|"&B35 -> MOLDURA GRUESA DIFÍCIL|TODAS
A36: FONDO MADERA | B36: TODAS | D36: SIN HERRAJE | F36: 0 | G36: 0 | H36: =IF(F36=0,0,F36*G36) -> 0 | J36: =A36&"|"&B36 -> FONDO MADERA|TODAS

Sheet COTIZADOR
A1: CAJIGA — COTIZADOR DE CLOSETS (HOJA INTERNA)
A3: PROYECTO: | B3: Closets Monte Tauro 290 — Vestidor Niñas | H3: FECHA: | I3: =TODAY() -> 46081
A4: CLIENTE: | B4: Monte Tauro 290 | H4: COTIZACIÓN #: | I4: COT-2025-001
A5: DIRECCIÓN: | H5: NIVEL (FUO): | I5: FUO 1.25
A6: ELABORÓ: | B6: Tu nombre | H6: VIGENCIA: | I6: 30 días
A8: FACTOR FUO ACTIVO: | D8: =IFERROR(VLOOKUP(I5,FUO!A5:C14,3,FALSE()),"⚠️ FUO no encontrado") -> 1.25 | G8: IVA: | I8: =IFERROR(VLOOKUP(I5,FUO!A5:E14,5,FALSE()),1.16) -> 1.16
B12: ↓ Selecciona componente | C12: ↓ Ver nota: qué mide según componente | D12: ↓ Ver nota: qué mide según componente | E12: ↓ Solo Cajón y Zapatera
A13: LADO | B13: COMPONENTE | C13: ANCHO (cm) | D13: LARGO/ALTO (cm) | E13: PROF. CAJÓN | F13: MATERIAL | G13: CANT. | H13: M² | I13: COSTO MAT. | J13: COSTO MO | K13: COSTO HERR. | L13: COSTO BASE | M13: PRECIO c/FUO | N13: PRECIO REDON. | O13: DSCTO % | P13: SUBTOTAL | Q13: NOTAS
B14: VESTIDOR NIÑAS
A15: V1 | B15: PISO CON ZOCLO | C15: 55 | D15: 100 | E15: — | F15: NOGAL | G15: 1 | H15: =IFERROR(IF(B15="","",(C15/100)*(D15/100)),"") -> 0.55 | I15: =IFERROR(IF(B15="","",_xlfn.LET(_xlpm.tamano,IF(H15<=0.5,"CHICO",IF(H15<=1,"MEDIANO","GRANDE")),_xlpm.clave,B15&"|"&_xlpm.tamano,_xlpm.fila,MATCH(_xlpm.clave,COSTOS_M2!$H$5:$H$67,0),_xlpm.mat_m2,INDEX(IF(F15="HUANACAXTLE",COSTOS_M2!$D$5:$D$67,IF(F15="ENCINO",COSTOS_M2!$E$5:$E$67,COSTOS_M2!$F$5:$F$67)),_xlpm.fila),_xlpm.cons_m2,INDEX(COSTOS_M2!$G$5:$G$67,_xlpm.fila),_xlpm.prof_factor,IF(AND(E15<>"—",E15<>"",ISNUMBER(E15)),POWER(E15/40,1.8),1),_xlpm.total_m2,(_xlpm.mat_m2+_xlpm.cons_m2)*H15*_xlpm.prof_factor*IF(C15>70,COSTOS_M2!$B$70,1)*IF(D15>244,COSTOS_M2!$B$71,1),_xlpm.total_m2)),"") -> 386.1 | J15: =IFERROR(IF(B15="","",INDEX(MANO_DE_OBRA!$P$10:$P$72,MATCH(B15&"|"&IF(H15<=0.5,"CHICO",IF(H15<=1,"MEDIANO","GRANDE")),MANO_DE_OBRA!$Q$10:$Q$72,0))),"") -> 469.28724 | K15: =IFERROR(IF(B15="","",_xlfn.LET(_xlpm.clave_prof,B15&"|"&E15,_xlpm.clave_todas,B15&"|TODAS",_xlpm.herr_prof,SUMIFS(HERRAJES!$H$5:$H$36,HERRAJES!$J$5:$J$36,_xlpm.clave_prof),_xlpm.herr_todas,SUMIFS(HERRAJES!$H$5:$H$36,HERRAJES!$J$5:$J$36,_xlpm.clave_todas),IF(_xlpm.herr_prof>0,_xlpm.herr_prof,_xlpm.herr_todas))),"") -> 0 | L15: =IFERROR(IF(B15="","",IF(I15="",0,I15)+IF(J15="",0,J15)+IF(K15="",0,K15)),"") -> 855.38724 | M15: =IFERROR(IF(L15="","",L15*$D$8),"") -> 1069.2341 | N15: =IFERROR(IF(M15="","",CEILING(M15,50)),"") -> 1100 | O15: 0 | P15: =IFERROR(IF(G15="","",G15*N15*(1-O15)),"") -> 1100
A16: V1 | B16: PISO CON ZOCLO | C16: 55 | D16: 175 | E16: — | F16: NOGAL | G16: 1 | H16: =IFERROR(IF(B16="","",(C16/100)*(D16/100)),"") -> 0.9625 | I16: =IFERROR(IF(B16="","",_xlfn.LET(_xlpm.tamano,IF(H16<=0.5,"CHICO",IF(H16<=1,"MEDIANO","GRANDE")),_xlpm.clave,B16&"|"&_xlpm.tamano,_xlpm.fila,MATCH(_xlpm.clave,COSTOS_M2!$H$5:$H$67,0),_xlpm.mat_m2,INDEX(IF(F16="HUANACAXTLE",COSTOS_M2!$D$5:$D$67,IF(F16="ENCINO",COSTOS_M2!$E$5:$E$67,COSTOS_M2!$F$5:$F$67)),_xlpm.fila),_xlpm.cons_m2,INDEX(COSTOS_M2!$G$5:$G$67,_xlpm.fila),_xlpm.prof_factor,IF(AND(E16<>"—",E16<>"",ISNUMBER(E16)),POWER(E16/40,1.8),1),_xlpm.total_m2,(_xlpm.mat_m2+_xlpm.cons_m2)*H16*_xlpm.prof_factor*IF(C16>70,COSTOS_M2!$B$70,1)*IF(D16>244,COSTOS_M2!$B$71,1),_xlpm.total_m2)),"") -> 675.675 | J16: =IFERROR(IF(B16="","",INDEX(MANO_DE_OBRA!$P$10:$P$72,MATCH(B16&"|"&IF(H16<=0.5,"CHICO",IF(H16<=1,"MEDIANO","GRANDE")),MANO_DE_OBRA!$Q$10:$Q$72,0))),"") -> 469.28724 | K16: =IFERROR(IF(B16="","",_xlfn.LET(_xlpm.clave_prof,B16&"|"&E16,_xlpm.clave_todas,B16&"|TODAS",_xlpm.herr_prof,SUMIFS(HERRAJES!$H$5:$H$36,HERRAJES!$J$5:$J$36,_xlpm.clave_prof),_xlpm.herr_todas,SUMIFS(HERRAJES!$H$5:$H$36,HERRAJES!$J$5:$J$36,_xlpm.clave_todas),IF(_xlpm.herr_prof>0,_xlpm.herr_prof,_xlpm.herr_todas))),"") -> 0 | L16: =IFERROR(IF(B16="","",IF(I16="",0,I16)+IF(J16="",0,J16)+IF(K16="",0,K16)),"") -> 1144.9622 | M16: =IFERROR(IF(L16="","",L16*$D$8),"") -> 1431.2028 | N16: =IFERROR(IF(M16="","",CEILING(M16,50)),"") -> 1450 | O16: 0 | P16: =IFERROR(IF(G16="","",G16*N16*(1-O16)),"") -> 1450
A17: V1 | B17: CIELO | C17: 55 | D17: 100 | E17: — | F17: NOGAL | G17: 1 | H17: =IFERROR(IF(B17="","",(C17/100)*(D17/100)),"") -> 0.55 | I17: =IFERROR(IF(B17="","",_xlfn.LET(_xlpm.tamano,IF(H17<=0.5,"CHICO",IF(H17<=1,"MEDIANO","GRANDE")),_xlpm.clave,B17&"|"&_xlpm.tamano,_xlpm.fila,MATCH(_xlpm.clave,COSTOS_M2!$H$5:$H$67,0),_xlpm.mat_m2,INDEX(IF(F17="HUANACAXTLE",COSTOS_M2!$D$5:$D$67,IF(F17="ENCINO",COSTOS_M2!$E$5:$E$67,COSTOS_M2!$F$5:$F$67)),_xlpm.fila),_xlpm.cons_m2,INDEX(COSTOS_M2!$G$5:$G$67,_xlpm.fila),_xlpm.prof_factor,IF(AND(E17<>"—",E17<>"",ISNUMBER(E17)),POWER(E17/40,1.8),1),_xlpm.total_m2,(_xlpm.mat_m2+_xlpm.cons_m2)*H17*_xlpm.prof_factor*IF(C17>70,COSTOS_M2!$B$70,1)*IF(D17>244,COSTOS_M2!$B$71,1),_xlpm.total_m2)),"") -> 459.8 | J17: =IFERROR(IF(B17="","",INDEX(MANO_DE_OBRA!$P$10:$P$72,MATCH(B17&"|"&IF(H17<=0.5,"CHICO",IF(H17<=1,"MEDIANO","GRANDE")),MANO_DE_OBRA!$Q$10:$Q$72,0))),"") -> 520.0504 | K17: =IFERROR(IF(B17="","",_xlfn.LET(_xlpm.clave_prof,B17&"|"&E17,_xlpm.clave_todas,B17&"|TODAS",_xlpm.herr_prof,SUMIFS(HERRAJES!$H$5:$H$36,HERRAJES!$J$5:$J$36,_xlpm.clave_prof),_xlpm.herr_todas,SUMIFS(HERRAJES!$H$5:$H$36,HERRAJES!$J$5:$J$36,_xlpm.clave_todas),IF(_xlpm.herr_prof>0,_xlpm.herr_prof,_xlpm.herr_todas))),"") -> 0 | L17: =IFERROR(IF(B17="","",IF(I17="",0,I17)+IF(J17="",0,J17)+IF(K17="",0,K17)),"") -> 979.8504 | M17: =IFERROR(IF(L17="","",L17*$D$8),"") -> 1224.813 | N17: =IFERROR(IF(M17="","",CEILING(M17,50)),"") -> 1250 | O17: 0 | P17: =IFERROR(IF(G17="","",G17*N17*(1-O17)),"") -> 1250
A18: V1 | B18: CIELO | C18: 55 | D18: 175 | E18: — | F18: NOGAL | G18: 1 | H18: =IFERROR(IF(B18="","",(C18/100)*(D18/100)),"") -> 0.9625 | I18: =IFERROR(IF(B18="","",_xlfn.LET(_xlpm.tamano,IF(H18<=0.5,"CHICO",IF(H18<=1,"MEDIANO","GRANDE")),_xlpm.clave,B18&"|"&_xlpm.tamano,_xlpm.fila,MATCH(_xlpm.clave,COSTOS_M2!$H$5:$H$67,0),_xlpm.mat_m2,INDEX(IF(F18="HUANACAXTLE",COSTOS_M2!$D$5:$D$67,IF(F18="ENCINO",COSTOS_M2!$E$5:$E$67,COSTOS_M2!$F$5:$F$67)),_xlpm.fila),_xlpm.cons_m2,INDEX(COSTOS_M2!$G$5:$G$67,_xlpm.fila),_xlpm.prof_factor,IF(AND(E18<>"—",E18<>"",ISNUMBER(E18)),POWER(E18/40,1.8),1),_xlpm.total_m2,(_xlpm.mat_m2+_xlpm.cons_m2)*H18*_xlpm.prof_factor*IF(C18>70,COSTOS_M2!$B$70,1)*IF(D18>244,COSTOS_M2!$B$71,1),_xlpm.total_m2)),"") -> 804.65 | J18: =IFERROR(IF(B18="","",INDEX(MANO_DE_OBRA!$P$10:$P$72,MATCH(B18&"|"&IF(H18<=0.5,"CHICO",IF(H18<=1,"MEDIANO","GRANDE")),MANO_DE_OBRA!$Q$10:$Q$72,0))),"") -> 520.0504 | K18: =IFERROR(IF(B18="","",_xlfn.LET(_xlpm.clave_prof,B18&"|"&E18,_xlpm.clave_todas,B18&"|TODAS",_xlpm.herr_prof,SUMIFS(HERRAJES!$H$5:$H$36,HERRAJES!$J$5:$J$36,_xlpm.clave_prof),_xlpm.herr_todas,SUMIFS(HERRAJES!$H$5:$H$36,HERRAJES!$J$5:$J$36,_xlpm.clave_todas),IF(_xlpm.herr_prof>0,_xlpm.herr_prof,_xlpm.herr_todas))),"") -> 0 | L18: =IFERROR(IF(B18="","",IF(I18="",0,I18)+IF(J18="",0,J18)+IF(K18="",0,K18)),"") -> 1324.7004 | M18: =IFERROR(IF(L18="","",L18*$D$8),"") -> 1655.8755 | N18: =IFERROR(IF(M18="","",CEILING(M18,50)),"") -> 1700 | O18: 0 | P18: =IFERROR(IF(G18="","",G18*N18*(1-O18)),"") -> 1700
A19: V1 | B19: PARAL 1 VISTA | C19: 55 | D19: 295 | E19: — | F19: NOGAL | G19: 2 | H19: =IFERROR(IF(B19="","",(C19/100)*(D19/100)),"") -> 1.6225 | I19: =IFERROR(IF(B19="","",_xlfn.LET(_xlpm.tamano,IF(H19<=0.5,"CHICO",IF(H19<=1,"MEDIANO","GRANDE")),_xlpm.clave,B19&"|"&_xlpm.tamano,_xlpm.fila,MATCH(_xlpm.clave,COSTOS_M2!$H$5:$H$67,0),_xlpm.mat_m2,INDEX(IF(F19="HUANACAXTLE",COSTOS_M2!$D$5:$D$67,IF(F19="ENCINO",COSTOS_M2!$E$5:$E$67,COSTOS_M2!$F$5:$F$67)),_xlpm.fila),_xlpm.cons_m2,INDEX(COSTOS_M2!$G$5:$G$67,_xlpm.fila),_xlpm.prof_factor,IF(AND(E19<>"—",E19<>"",ISNUMBER(E19)),POWER(E19/40,1.8),1),_xlpm.total_m2,(_xlpm.mat_m2+_xlpm.cons_m2)*H19*_xlpm.prof_factor*IF(C19>70,COSTOS_M2!$B$70,1)*IF(D19>244,COSTOS_M2!$B$71,1),_xlpm.total_m2)),"") -> 1453.2733 | J19: =IFERROR(IF(B19="","",INDEX(MANO_DE_OBRA!$P$10:$P$72,MATCH(B19&"|"&IF(H19<=0.5,"CHICO",IF(H19<=1,"MEDIANO","GRANDE")),MANO_DE_OBRA!$Q$10:$Q$72,0))),"") -> 587.22913 | K19: =IFERROR(IF(B19="","",_xlfn.LET(_xlpm.clave_prof,B19&"|"&E19,_xlpm.clave_todas,B19&"|TODAS",_xlpm.herr_prof,SUMIFS(HERRAJES!$H$5:$H$36,HERRAJES!$J$5:$J$36,_xlpm.clave_prof),_xlpm.herr_todas,SUMIFS(HERRAJES!$H$5:$H$36,HERRAJES!$J$5:$J$36,_xlpm.clave_todas),IF(_xlpm.herr_prof>0,_xlpm.herr_prof,_xlpm.herr_todas))),"") -> 0 | L19: =IFERROR(IF(B19="","",IF(I19="",0,I19)+IF(J19="",0,J19)+IF(K19="",0,K19)),"") -> 2040.5024 | M19: =IFERROR(IF(L19="","",L19*$D$8),"") -> 2550.628 | N19: =IFERROR(IF(M19="","",CEILING(M19,50)),"") -> 2600 | O19: 0 | P19: =IFERROR(IF(G19="","",G19*N19*(1-O19)),"") -> 5200
A20: V1 | B20: PARAL DELGADO 2V | C20: 55 | D20: 295 | E20: — | F20: NOGAL | G20: 2 | H20: =IFERROR(IF(B20="","",(C20/100)*(D20/100)),"") -> 1.6225 | I20: =IFERROR(IF(B20="","",_xlfn.LET(_xlpm.tamano,IF(H20<=0.5,"CHICO",IF(H20<=1,"MEDIANO","GRANDE")),_xlpm.clave,B20&"|"&_xlpm.tamano,_xlpm.fila,MATCH(_xlpm.clave,COSTOS_M2!$H$5:$H$67,0),_xlpm.mat_m2,INDEX(IF(F20="HUANACAXTLE",COSTOS_M2!$D$5:$D$67,IF(F20="ENCINO",COSTOS_M2!$E$5:$E$67,COSTOS_M2!$F$5:$F$67)),_xlpm.fila),_xlpm.cons_m2,INDEX(COSTOS_M2!$G$5:$G$67,_xlpm.fila),_xlpm.prof_factor,IF(AND(E20<>"—",E20<>"",ISNUMBER(E20)),POWER(E20/40,1.8),1),_xlpm.total_m2,(_xlpm.mat_m2+_xlpm.cons_m2)*H20*_xlpm.prof_factor*IF(C20>70,COSTOS_M2!$B$70,1)*IF(D20>244,COSTOS_M2!$B$71,1),_xlpm.total_m2)),"") -> 1571.3913 | J20: =IFERROR(IF(B20="","",INDEX(MANO_DE_OBRA!$P$10:$P$72,MATCH(B20&"|"&IF(H20<=0.5,"CHICO",IF(H20<=1,"MEDIANO","GRANDE")),MANO_DE_OBRA!$Q$10:$Q$72,0))),"") -> 725.196 | K20: =IFERROR(IF(B20="","",_xlfn.LET(_xlpm.clave_prof,B20&"|"&E20,_xlpm.clave_todas,B20&"|TODAS",_xlpm.herr_prof,SUMIFS(HERRAJES!$H$5:$H$36,HERRAJES!$J$5:$J$36,_xlpm.clave_prof),_xlpm.herr_todas,SUMIFS(HERRAJES!$H$5:$H$36,HERRAJES!$J$5:$J$36,_xlpm.clave_todas),IF(_xlpm.herr_prof>0,_xlpm.herr_prof,_xlpm.herr_todas))),"") -> 0 | L20: =IFERROR(IF(B20="","",IF(I20="",0,I20)+IF(J20="",0,J20)+IF(K20="",0,K20)),"") -> 2296.5873 | M20: =IFERROR(IF(L20="","",L20*$D$8),"") -> 2870.7341 | N20: =IFERROR(IF(M20="","",CEILING(M20,50)),"") -> 2900 | O20: 0 | P20: =IFERROR(IF(G20="","",G20*N20*(1-O20)),"") -> 5800
A21: V1 | B21: ZAPATERA EXTRAÍBLE | C21: 100 | D21: 55 | E21: 55 | F21: NOGAL | G21: 4 | H21: =IFERROR(IF(B21="","",(C21/100)*(D21/100)),"") -> 0.55 | I21: =IFERROR(IF(B21="","",_xlfn.LET(_xlpm.tamano,IF(H21<=0.5,"CHICO",IF(H21<=1,"MEDIANO","GRANDE")),_xlpm.clave,B21&"|"&_xlpm.tamano,_xlpm.fila,MATCH(_xlpm.clave,COSTOS_M2!$H$5:$H$67,0),_xlpm.mat_m2,INDEX(IF(F21="HUANACAXTLE",COSTOS_M2!$D$5:$D$67,IF(F21="ENCINO",COSTOS_M2!$E$5:$E$67,COSTOS_M2!$F$5:$F$67)),_xlpm.fila),_xlpm.cons_m2,INDEX(COSTOS_M2!$G$5:$G$67,_xlpm.fila),_xlpm.prof_factor,IF(AND(E21<>"—",E21<>"",ISNUMBER(E21)),POWER(E21/40,1.8),1),_xlpm.total_m2,(_xlpm.mat_m2+_xlpm.cons_m2)*H21*_xlpm.prof_factor*IF(C21>70,COSTOS_M2!$B$70,1)*IF(D21>244,COSTOS_M2!$B$71,1),_xlpm.total_m2)),"") -> 738.19973 | J21: =IFERROR(IF(B21="","",INDEX(MANO_DE_OBRA!$P$10:$P$72,MATCH(B21&"|"&IF(H21<=0.5,"CHICO",IF(H21<=1,"MEDIANO","GRANDE")),MANO_DE_OBRA!$Q$10:$Q$72,0))),"") -> 410.25956 | K21: =IFERROR(IF(B21="","",_xlfn.LET(_xlpm.clave_prof,B21&"|"&E21,_xlpm.clave_todas,B21&"|TODAS",_xlpm.herr_prof,SUMIFS(HERRAJES!$H$5:$H$36,HERRAJES!$J$5:$J$36,_xlpm.clave_prof),_xlpm.herr_todas,SUMIFS(HERRAJES!$H$5:$H$36,HERRAJES!$J$5:$J$36,_xlpm.clave_todas),IF(_xlpm.herr_prof>0,_xlpm.herr_prof,_xlpm.herr_todas))),"") -> 50.52 | L21: =IFERROR(IF(B21="","",IF(I21="",0,I21)+IF(J21="",0,J21)+IF(K21="",0,K21)),"") -> 1198.9793 | M21: =IFERROR(IF(L21="","",L21*$D$8),"") -> 1498.7241 | N21: =IFERROR(IF(M21="","",CEILING(M21,50)),"") -> 1500 | O21: 0 | P21: =IFERROR(IF(G21="","",G21*N21*(1-O21)),"") -> 6000
A22: V1 | B22: ENTREPAÑO DELGADO | C22: 55 | D22: 100 | E22: — | F22: NOGAL | G22: 2 | H22: =IFERROR(IF(B22="","",(C22/100)*(D22/100)),"") -> 0.55 | I22: =IFERROR(IF(B22="","",_xlfn.LET(_xlpm.tamano,IF(H22<=0.5,"CHICO",IF(H22<=1,"MEDIANO","GRANDE")),_xlpm.clave,B22&"|"&_xlpm.tamano,_xlpm.fila,MATCH(_xlpm.clave,COSTOS_M2!$H$5:$H$67,0),_xlpm.mat_m2,INDEX(IF(F22="HUANACAXTLE",COSTOS_M2!$D$5:$D$67,IF(F22="ENCINO",COSTOS_M2!$E$5:$E$67,COSTOS_M2!$F$5:$F$67)),_xlpm.fila),_xlpm.cons_m2,INDEX(COSTOS_M2!$G$5:$G$67,_xlpm.fila),_xlpm.prof_factor,IF(AND(E22<>"—",E22<>"",ISNUMBER(E22)),POWER(E22/40,1.8),1),_xlpm.total_m2,(_xlpm.mat_m2+_xlpm.cons_m2)*H22*_xlpm.prof_factor*IF(C22>70,COSTOS_M2!$B$70,1)*IF(D22>244,COSTOS_M2!$B$71,1),_xlpm.total_m2)),"") -> 431.75 | J22: =IFERROR(IF(B22="","",INDEX(MANO_DE_OBRA!$P$10:$P$72,MATCH(B22&"|"&IF(H22<=0.5,"CHICO",IF(H22<=1,"MEDIANO","GRANDE")),MANO_DE_OBRA!$Q$10:$Q$72,0))),"") -> 400.5588 | K22: =IFERROR(IF(B22="","",_xlfn.LET(_xlpm.clave_prof,B22&"|"&E22,_xlpm.clave_todas,B22&"|TODAS",_xlpm.herr_prof,SUMIFS(HERRAJES!$H$5:$H$36,HERRAJES!$J$5:$J$36,_xlpm.clave_prof),_xlpm.herr_todas,SUMIFS(HERRAJES!$H$5:$H$36,HERRAJES!$J$5:$J$36,_xlpm.clave_todas),IF(_xlpm.herr_prof>0,_xlpm.herr_prof,_xlpm.herr_todas))),"") -> 0 | L22: =IFERROR(IF(B22="","",IF(I22="",0,I22)+IF(J22="",0,J22)+IF(K22="",0,K22)),"") -> 832.3088 | M22: =IFERROR(IF(L22="","",L22*$D$8),"") -> 1040.386 | N22: =IFERROR(IF(M22="","",CEILING(M22,50)),"") -> 1050 | O22: 0 | P22: =IFERROR(IF(G22="","",G22*N22*(1-O22)),"") -> 2100
A23: V1 | B23: ENTREPAÑO DELGADO | C23: 55 | D23: 71 | E23: — | F23: NOGAL | G23: 6 | H23: =IFERROR(IF(B23="","",(C23/100)*(D23/100)),"") -> 0.3905 | I23: =IFERROR(IF(B23="","",_xlfn.LET(_xlpm.tamano,IF(H23<=0.5,"CHICO",IF(H23<=1,"MEDIANO","GRANDE")),_xlpm.clave,B23&"|"&_xlpm.tamano,_xlpm.fila,MATCH(_xlpm.clave,COSTOS_M2!$H$5:$H$67,0),_xlpm.mat_m2,INDEX(IF(F23="HUANACAXTLE",COSTOS_M2!$D$5:$D$67,IF(F23="ENCINO",COSTOS_M2!$E$5:$E$67,COSTOS_M2!$F$5:$F$67)),_xlpm.fila),_xlpm.cons_m2,INDEX(COSTOS_M2!$G$5:$G$67,_xlpm.fila),_xlpm.prof_factor,IF(AND(E23<>"—",E23<>"",ISNUMBER(E23)),POWER(E23/40,1.8),1),_xlpm.total_m2,(_xlpm.mat_m2+_xlpm.cons_m2)*H23*_xlpm.prof_factor*IF(C23>70,COSTOS_M2!$B$70,1)*IF(D23>244,COSTOS_M2!$B$71,1),_xlpm.total_m2)),"") -> 326.0675 | J23: =IFERROR(IF(B23="","",INDEX(MANO_DE_OBRA!$P$10:$P$72,MATCH(B23&"|"&IF(H23<=0.5,"CHICO",IF(H23<=1,"MEDIANO","GRANDE")),MANO_DE_OBRA!$Q$10:$Q$72,0))),"") -> 265.8015 | K23: =IFERROR(IF(B23="","",_xlfn.LET(_xlpm.clave_prof,B23&"|"&E23,_xlpm.clave_todas,B23&"|TODAS",_xlpm.herr_prof,SUMIFS(HERRAJES!$H$5:$H$36,HERRAJES!$J$5:$J$36,_xlpm.clave_prof),_xlpm.herr_todas,SUMIFS(HERRAJES!$H$5:$H$36,HERRAJES!$J$5:$J$36,_xlpm.clave_todas),IF(_xlpm.herr_prof>0,_xlpm.herr_prof,_xlpm.herr_todas))),"") -> 0 | L23: =IFERROR(IF(B23="","",IF(I23="",0,I23)+IF(J23="",0,J23)+IF(K23="",0,K23)),"") -> 591.869 | M23: =IFERROR(IF(L23="","",L23*$D$8),"") -> 739.83625 | N23: =IFERROR(IF(M23="","",CEILING(M23,50)),"") -> 750 | O23: 0 | P23: =IFERROR(IF(G23="","",G23*N23*(1-O23)),"") -> 4500
A24: V1 | B24: CAJÓN | C24: 71 | D24: 22 | E24: 55 | F24: NOGAL | G24: 4 | H24: =IFERROR(IF(B24="","",(C24/100)*(D24/100)),"") -> 0.1562 | I24: =IFERROR(IF(B24="","",_xlfn.LET(_xlpm.tamano,IF(H24<=0.5,"CHICO",IF(H24<=1,"MEDIANO","GRANDE")),_xlpm.clave,B24&"|"&_xlpm.tamano,_xlpm.fila,MATCH(_xlpm.clave,COSTOS_M2!$H$5:$H$67,0),_xlpm.mat_m2,INDEX(IF(F24="HUANACAXTLE",COSTOS_M2!$D$5:$D$67,IF(F24="ENCINO",COSTOS_M2!$E$5:$E$67,COSTOS_M2!$F$5:$F$67)),_xlpm.fila),_xlpm.cons_m2,INDEX(COSTOS_M2!$G$5:$G$67,_xlpm.fila),_xlpm.prof_factor,IF(AND(E24<>"—",E24<>"",ISNUMBER(E24)),POWER(E24/40,1.8),1),_xlpm.total_m2,(_xlpm.mat_m2+_xlpm.cons_m2)*H24*_xlpm.prof_factor*IF(C24>70,COSTOS_M2!$B$70,1)*IF(D24>244,COSTOS_M2!$B$71,1),_xlpm.total_m2)),"") -> 479.09416 | J24: =IFERROR(IF(B24="","",INDEX(MANO_DE_OBRA!$P$10:$P$72,MATCH(B24&"|"&IF(H24<=0.5,"CHICO",IF(H24<=1,"MEDIANO","GRANDE")),MANO_DE_OBRA!$Q$10:$Q$72,0))),"") -> 434.36213 | K24: =IFERROR(IF(B24="","",_xlfn.LET(_xlpm.clave_prof,B24&"|"&E24,_xlpm.clave_todas,B24&"|TODAS",_xlpm.herr_prof,SUMIFS(HERRAJES!$H$5:$H$36,HERRAJES!$J$5:$J$36,_xlpm.clave_prof),_xlpm.herr_todas,SUMIFS(HERRAJES!$H$5:$H$36,HERRAJES!$J$5:$J$36,_xlpm.clave_todas),IF(_xlpm.herr_prof>0,_xlpm.herr_prof,_xlpm.herr_todas))),"") -> 50.52 | L24: =IFERROR(IF(B24="","",IF(I24="",0,I24)+IF(J24="",0,J24)+IF(K24="",0,K24)),"") -> 963.9763 | M24: =IFERROR(IF(L24="","",L24*$D$8),"") -> 1204.9704 | N24: =IFERROR(IF(M24="","",CEILING(M24,50)),"") -> 1250 | O24: 0 | P24: =IFERROR(IF(G24="","",G24*N24*(1-O24)),"") -> 5000
A25: V1 | B25: TUBO COLGAR | C25: ESPECIAL | D25: 100 | E25: — | F25: NOGAL | G25: 4 | H25: =IFERROR(IF(B25="","",(C25/100)*(D25/100)),"") | I25: =IFERROR(IF(B25="","",_xlfn.LET(_xlpm.tamano,IF(H25<=0.5,"CHICO",IF(H25<=1,"MEDIANO","GRANDE")),_xlpm.clave,B25&"|"&_xlpm.tamano,_xlpm.fila,MATCH(_xlpm.clave,COSTOS_M2!$H$5:$H$67,0),_xlpm.mat_m2,INDEX(IF(F25="HUANACAXTLE",COSTOS_M2!$D$5:$D$67,IF(F25="ENCINO",COSTOS_M2!$E$5:$E$67,COSTOS_M2!$F$5:$F$67)),_xlpm.fila),_xlpm.cons_m2,INDEX(COSTOS_M2!$G$5:$G$67,_xlpm.fila),_xlpm.prof_factor,IF(AND(E25<>"—",E25<>"",ISNUMBER(E25)),POWER(E25/40,1.8),1),_xlpm.total_m2,(_xlpm.mat_m2+_xlpm.cons_m2)*H25*_xlpm.prof_factor*IF(C25>70,COSTOS_M2!$B$70,1)*IF(D25>244,COSTOS_M2!$B$71,1),_xlpm.total_m2)),"") | J25: =IFERROR(IF(B25="","",INDEX(MANO_DE_OBRA!$P$10:$P$72,MATCH(B25&"|"&IF(H25<=0.5,"CHICO",IF(H25<=1,"MEDIANO","GRANDE")),MANO_DE_OBRA!$Q$10:$Q$72,0))),"") -> 25.593 | K25: =IFERROR(IF(B25="","",_xlfn.LET(_xlpm.clave_prof,B25&"|"&E25,_xlpm.clave_todas,B25&"|TODAS",_xlpm.herr_prof,SUMIFS(HERRAJES!$H$5:$H$36,HERRAJES!$J$5:$J$36,_xlpm.clave_prof),_xlpm.herr_todas,SUMIFS(HERRAJES!$H$5:$H$36,HERRAJES!$J$5:$J$36,_xlpm.clave_todas),IF(_xlpm.herr_prof>0,_xlpm.herr_prof,_xlpm.herr_todas))),"") -> 2.74 | L25: =IFERROR(IF(B25="","",IF(I25="",0,I25)+IF(J25="",0,J25)+IF(K25="",0,K25)),"") -> 28.333 | M25: =IFERROR(IF(L25="","",L25*$D$8),"") -> 35.41625 | N25: =IFERROR(IF(M25="","",CEILING(M25,50)),"") -> 50 | O25: 0 | P25: =IFERROR(IF(G25="","",G25*N25*(1-O25)),"") -> 200
A26: V1 | B26: FONDO MADERA | C26: 275 | D26: 305 | E26: — | F26: NOGAL | G26: 1 | H26: =IFERROR(IF(B26="","",(C26/100)*(D26/100)),"") -> 8.3875 | I26: =IFERROR(IF(B26="","",_xlfn.LET(_xlpm.tamano,IF(H26<=0.5,"CHICO",IF(H26<=1,"MEDIANO","GRANDE")),_xlpm.clave,B26&"|"&_xlpm.tamano,_xlpm.fila,MATCH(_xlpm.clave,COSTOS_M2!$H$5:$H$67,0),_xlpm.mat_m2,INDEX(IF(F26="HUANACAXTLE",COSTOS_M2!$D$5:$D$67,IF(F26="ENCINO",COSTOS_M2!$E$5:$E$67,COSTOS_M2!$F$5:$F$67)),_xlpm.fila),_xlpm.cons_m2,INDEX(COSTOS_M2!$G$5:$G$67,_xlpm.fila),_xlpm.prof_factor,IF(AND(E26<>"—",E26<>"",ISNUMBER(E26)),POWER(E26/40,1.8),1),_xlpm.total_m2,(_xlpm.mat_m2+_xlpm.cons_m2)*H26*_xlpm.prof_factor*IF(C26>70,COSTOS_M2!$B$70,1)*IF(D26>244,COSTOS_M2!$B$71,1),_xlpm.total_m2)),"") -> 3331.0956 | J26: =IFERROR(IF(B26="","",INDEX(MANO_DE_OBRA!$P$10:$P$72,MATCH(B26&"|"&IF(H26<=0.5,"CHICO",IF(H26<=1,"MEDIANO","GRANDE")),MANO_DE_OBRA!$Q$10:$Q$72,0))),"") -> 295.7955 | K26: =IFERROR(IF(B26="","",_xlfn.LET(_xlpm.clave_prof,B26&"|"&E26,_xlpm.clave_todas,B26&"|TODAS",_xlpm.herr_prof,SUMIFS(HERRAJES!$H$5:$H$36,HERRAJES!$J$5:$J$36,_xlpm.clave_prof),_xlpm.herr_todas,SUMIFS(HERRAJES!$H$5:$H$36,HERRAJES!$J$5:$J$36,_xlpm.clave_todas),IF(_xlpm.herr_prof>0,_xlpm.herr_prof,_xlpm.herr_todas))),"") -> 0 | L26: =IFERROR(IF(B26="","",IF(I26="",0,I26)+IF(J26="",0,J26)+IF(K26="",0,K26)),"") -> 3626.8911 | M26: =IFERROR(IF(L26="","",L26*$D$8),"") -> 4533.6139 | N26: =IFERROR(IF(M26="","",CEILING(M26,50)),"") -> 4550 | O26: 0 | P26: =IFERROR(IF(G26="","",G26*N26*(1-O26)),"") -> 4550
A27: V1 | B27: MOLDURA DIFÍCIL | C27: 5 | D27: 550 | E27: — | F27: NOGAL | G27: 1 | H27: =IFERROR(IF(B27="","",(C27/100)*(D27/100)),"") -> 0.275 | I27: =IFERROR(IF(B27="","",_xlfn.LET(_xlpm.tamano,IF(H27<=0.5,"CHICO",IF(H27<=1,"MEDIANO","GRANDE")),_xlpm.clave,B27&"|"&_xlpm.tamano,_xlpm.fila,MATCH(_xlpm.clave,COSTOS_M2!$H$5:$H$67,0),_xlpm.mat_m2,INDEX(IF(F27="HUANACAXTLE",COSTOS_M2!$D$5:$D$67,IF(F27="ENCINO",COSTOS_M2!$E$5:$E$67,COSTOS_M2!$F$5:$F$67)),_xlpm.fila),_xlpm.cons_m2,INDEX(COSTOS_M2!$G$5:$G$67,_xlpm.fila),_xlpm.prof_factor,IF(AND(E27<>"—",E27<>"",ISNUMBER(E27)),POWER(E27/40,1.8),1),_xlpm.total_m2,(_xlpm.mat_m2+_xlpm.cons_m2)*H27*_xlpm.prof_factor*IF(C27>70,COSTOS_M2!$B$70,1)*IF(D27>244,COSTOS_M2!$B$71,1),_xlpm.total_m2)),"") -> 1841.125 | J27: =IFERROR(IF(B27="","",INDEX(MANO_DE_OBRA!$P$10:$P$72,MATCH(B27&"|"&IF(H27<=0.5,"CHICO",IF(H27<=1,"MEDIANO","GRANDE")),MANO_DE_OBRA!$Q$10:$Q$72,0))),"") -> 477.459 | K27: =IFERROR(IF(B27="","",_xlfn.LET(_xlpm.clave_prof,B27&"|"&E27,_xlpm.clave_todas,B27&"|TODAS",_xlpm.herr_prof,SUMIFS(HERRAJES!$H$5:$H$36,HERRAJES!$J$5:$J$36,_xlpm.clave_prof),_xlpm.herr_todas,SUMIFS(HERRAJES!$H$5:$H$36,HERRAJES!$J$5:$J$36,_xlpm.clave_todas),IF(_xlpm.herr_prof>0,_xlpm.herr_prof,_xlpm.herr_todas))),"") -> 0 | L27: =IFERROR(IF(B27="","",IF(I27="",0,I27)+IF(J27="",0,J27)+IF(K27="",0,K27)),"") -> 2318.584 | M27: =IFERROR(IF(L27="","",L27*$D$8),"") -> 2898.23 | N27: =IFERROR(IF(M27="","",CEILING(M27,50)),"") -> 2900 | O27: 0 | P27: =IFERROR(IF(G27="","",G27*N27*(1-O27)),"") -> 2900
A28: V2 | B28: PISO CON ZOCLO | C28: 55 | D28: 195 | E28: — | F28: NOGAL | G28: 1 | H28: =IFERROR(IF(B28="","",(C28/100)*(D28/100)),"") -> 1.0725 | I28: =IFERROR(IF(B28="","",_xlfn.LET(_xlpm.tamano,IF(H28<=0.5,"CHICO",IF(H28<=1,"MEDIANO","GRANDE")),_xlpm.clave,B28&"|"&_xlpm.tamano,_xlpm.fila,MATCH(_xlpm.clave,COSTOS_M2!$H$5:$H$67,0),_xlpm.mat_m2,INDEX(IF(F28="HUANACAXTLE",COSTOS_M2!$D$5:$D$67,IF(F28="ENCINO",COSTOS_M2!$E$5:$E$67,COSTOS_M2!$F$5:$F$67)),_xlpm.fila),_xlpm.cons_m2,INDEX(COSTOS_M2!$G$5:$G$67,_xlpm.fila),_xlpm.prof_factor,IF(AND(E28<>"—",E28<>"",ISNUMBER(E28)),POWER(E28/40,1.8),1),_xlpm.total_m2,(_xlpm.mat_m2+_xlpm.cons_m2)*H28*_xlpm.prof_factor*IF(C28>70,COSTOS_M2!$B$70,1)*IF(D28>244,COSTOS_M2!$B$71,1),_xlpm.total_m2)),"") -> 721.7925 | J28: =IFERROR(IF(B28="","",INDEX(MANO_DE_OBRA!$P$10:$P$72,MATCH(B28&"|"&IF(H28<=0.5,"CHICO",IF(H28<=1,"MEDIANO","GRANDE")),MANO_DE_OBRA!$Q$10:$Q$72,0))),"") -> 614.34549 | K28: =IFERROR(IF(B28="","",_xlfn.LET(_xlpm.clave_prof,B28&"|"&E28,_xlpm.clave_todas,B28&"|TODAS",_xlpm.herr_prof,SUMIFS(HERRAJES!$H$5:$H$36,HERRAJES!$J$5:$J$36,_xlpm.clave_prof),_xlpm.herr_todas,SUMIFS(HERRAJES!$H$5:$H$36,HERRAJES!$J$5:$J$36,_xlpm.clave_todas),IF(_xlpm.herr_prof>0,_xlpm.herr_prof,_xlpm.herr_todas))),"") -> 0 | L28: =IFERROR(IF(B28="","",IF(I28="",0,I28)+IF(J28="",0,J28)+IF(K28="",0,K28)),"") -> 1336.138 | M28: =IFERROR(IF(L28="","",L28*$D$8),"") -> 1670.1725 | N28: =IFERROR(IF(M28="","",CEILING(M28,50)),"") -> 1700 | O28: 0 | P28: =IFERROR(IF(G28="","",G28*N28*(1-O28)),"") -> 1700
A29: V2 | B29: CIELO | C29: 55 | D29: 195 | E29: — | F29: NOGAL | G29: 1 | H29: =IFERROR(IF(B29="","",(C29/100)*(D29/100)),"") -> 1.0725 | I29: =IFERROR(IF(B29="","",_xlfn.LET(_xlpm.tamano,IF(H29<=0.5,"CHICO",IF(H29<=1,"MEDIANO","GRANDE")),_xlpm.clave,B29&"|"&_xlpm.tamano,_xlpm.fila,MATCH(_xlpm.clave,COSTOS_M2!$H$5:$H$67,0),_xlpm.mat_m2,INDEX(IF(F29="HUANACAXTLE",COSTOS_M2!$D$5:$D$67,IF(F29="ENCINO",COSTOS_M2!$E$5:$E$67,COSTOS_M2!$F$5:$F$67)),_xlpm.fila),_xlpm.cons_m2,INDEX(COSTOS_M2!$G$5:$G$67,_xlpm.fila),_xlpm.prof_factor,IF(AND(E29<>"—",E29<>"",ISNUMBER(E29)),POWER(E29/40,1.8),1),_xlpm.total_m2,(_xlpm.mat_m2+_xlpm.cons_m2)*H29*_xlpm.prof_factor*IF(C29>70,COSTOS_M2!$B$70,1)*IF(D29>244,COSTOS_M2!$B$71,1),_xlpm.total_m2)),"") -> 866.58 | J29: =IFERROR(IF(B29="","",INDEX(MANO_DE_OBRA!$P$10:$P$72,MATCH(B29&"|"&IF(H29<=0.5,"CHICO",IF(H29<=1,"MEDIANO","GRANDE")),MANO_DE_OBRA!$Q$10:$Q$72,0))),"") -> 762.95904 | K29: =IFERROR(IF(B29="","",_xlfn.LET(_xlpm.clave_prof,B29&"|"&E29,_xlpm.clave_todas,B29&"|TODAS",_xlpm.herr_prof,SUMIFS(HERRAJES!$H$5:$H$36,HERRAJES!$J$5:$J$36,_xlpm.clave_prof),_xlpm.herr_todas,SUMIFS(HERRAJES!$H$5:$H$36,HERRAJES!$J$5:$J$36,_xlpm.clave_todas),IF(_xlpm.herr_prof>0,_xlpm.herr_prof,_xlpm.herr_todas))),"") -> 0 | L29: =IFERROR(IF(B29="","",IF(I29="",0,I29)+IF(J29="",0,J29)+IF(K29="",0,K29)),"") -> 1629.539 | M29: =IFERROR(IF(L29="","",L29*$D$8),"") -> 2036.9238 | N29: =IFERROR(IF(M29="","",CEILING(M29,50)),"") -> 2050 | O29: 0 | P29: =IFERROR(IF(G29="","",G29*N29*(1-O29)),"") -> 2050
A30: V2 | B30: PARAL 1 VISTA | C30: 55 | D30: 295 | E30: — | F30: NOGAL | G30: 1 | H30: =IFERROR(IF(B30="","",(C30/100)*(D30/100)),"") -> 1.6225 | I30: =IFERROR(IF(B30="","",_xlfn.LET(_xlpm.tamano,IF(H30<=0.5,"CHICO",IF(H30<=1,"MEDIANO","GRANDE")),_xlpm.clave,B30&"|"&_xlpm.tamano,_xlpm.fila,MATCH(_xlpm.clave,COSTOS_M2!$H$5:$H$67,0),_xlpm.mat_m2,INDEX(IF(F30="HUANACAXTLE",COSTOS_M2!$D$5:$D$67,IF(F30="ENCINO",COSTOS_M2!$E$5:$E$67,COSTOS_M2!$F$5:$F$67)),_xlpm.fila),_xlpm.cons_m2,INDEX(COSTOS_M2!$G$5:$G$67,_xlpm.fila),_xlpm.prof_factor,IF(AND(E30<>"—",E30<>"",ISNUMBER(E30)),POWER(E30/40,1.8),1),_xlpm.total_m2,(_xlpm.mat_m2+_xlpm.cons_m2)*H30*_xlpm.prof_factor*IF(C30>70,COSTOS_M2!$B$70,1)*IF(D30>244,COSTOS_M2!$B$71,1),_xlpm.total_m2)),"") -> 1453.2733 | J30: =IFERROR(IF(B30="","",INDEX(MANO_DE_OBRA!$P$10:$P$72,MATCH(B30&"|"&IF(H30<=0.5,"CHICO",IF(H30<=1,"MEDIANO","GRANDE")),MANO_DE_OBRA!$Q$10:$Q$72,0))),"") -> 587.22913 | K30: =IFERROR(IF(B30="","",_xlfn.LET(_xlpm.clave_prof,B30&"|"&E30,_xlpm.clave_todas,B30&"|TODAS",_xlpm.herr_prof,SUMIFS(HERRAJES!$H$5:$H$36,HERRAJES!$J$5:$J$36,_xlpm.clave_prof),_xlpm.herr_todas,SUMIFS(HERRAJES!$H$5:$H$36,HERRAJES!$J$5:$J$36,_xlpm.clave_todas),IF(_xlpm.herr_prof>0,_xlpm.herr_prof,_xlpm.herr_todas))),"") -> 0 | L30: =IFERROR(IF(B30="","",IF(I30="",0,I30)+IF(J30="",0,J30)+IF(K30="",0,K30)),"") -> 2040.5024 | M30: =IFERROR(IF(L30="","",L30*$D$8),"") -> 2550.628 | N30: =IFERROR(IF(M30="","",CEILING(M30,50)),"") -> 2600 | O30: 0 | P30: =IFERROR(IF(G30="","",G30*N30*(1-O30)),"") -> 2600
A31: V2 | B31: PARAL 2 VISTAS | C31: 55 | D31: 295 | E31: — | F31: NOGAL | G31: 1 | H31: =IFERROR(IF(B31="","",(C31/100)*(D31/100)),"") -> 1.6225 | I31: =IFERROR(IF(B31="","",_xlfn.LET(_xlpm.tamano,IF(H31<=0.5,"CHICO",IF(H31<=1,"MEDIANO","GRANDE")),_xlpm.clave,B31&"|"&_xlpm.tamano,_xlpm.fila,MATCH(_xlpm.clave,COSTOS_M2!$H$5:$H$67,0),_xlpm.mat_m2,INDEX(IF(F31="HUANACAXTLE",COSTOS_M2!$D$5:$D$67,IF(F31="ENCINO",COSTOS_M2!$E$5:$E$67,COSTOS_M2!$F$5:$F$67)),_xlpm.fila),_xlpm.cons_m2,INDEX(COSTOS_M2!$G$5:$G$67,_xlpm.fila),_xlpm.prof_factor,IF(AND(E31<>"—",E31<>"",ISNUMBER(E31)),POWER(E31/40,1.8),1),_xlpm.total_m2,(_xlpm.mat_m2+_xlpm.cons_m2)*H31*_xlpm.prof_factor*IF(C31>70,COSTOS_M2!$B$70,1)*IF(D31>244,COSTOS_M2!$B$71,1),_xlpm.total_m2)),"") -> 2389.7803 | J31: =IFERROR(IF(B31="","",INDEX(MANO_DE_OBRA!$P$10:$P$72,MATCH(B31&"|"&IF(H31<=0.5,"CHICO",IF(H31<=1,"MEDIANO","GRANDE")),MANO_DE_OBRA!$Q$10:$Q$72,0))),"") -> 751.15698 | K31: =IFERROR(IF(B31="","",_xlfn.LET(_xlpm.clave_prof,B31&"|"&E31,_xlpm.clave_todas,B31&"|TODAS",_xlpm.herr_prof,SUMIFS(HERRAJES!$H$5:$H$36,HERRAJES!$J$5:$J$36,_xlpm.clave_prof),_xlpm.herr_todas,SUMIFS(HERRAJES!$H$5:$H$36,HERRAJES!$J$5:$J$36,_xlpm.clave_todas),IF(_xlpm.herr_prof>0,_xlpm.herr_prof,_xlpm.herr_todas))),"") -> 0 | L31: =IFERROR(IF(B31="","",IF(I31="",0,I31)+IF(J31="",0,J31)+IF(K31="",0,K31)),"") -> 3140.9372 | M31: =IFERROR(IF(L31="","",L31*$D$8),"") -> 3926.1715 | N31: =IFERROR(IF(M31="","",CEILING(M31,50)),"") -> 3950 | O31: 0 | P31: =IFERROR(IF(G31="","",G31*N31*(1-O31)),"") -> 3950
A32: V2 | B32: PARAL DELGADO 2V | C32: 55 | D32: 295 | E32: — | F32: NOGAL | G32: 1 | H32: =IFERROR(IF(B32="","",(C32/100)*(D32/100)),"") -> 1.6225 | I32: =IFERROR(IF(B32="","",_xlfn.LET(_xlpm.tamano,IF(H32<=0.5,"CHICO",IF(H32<=1,"MEDIANO","GRANDE")),_xlpm.clave,B32&"|"&_xlpm.tamano,_xlpm.fila,MATCH(_xlpm.clave,COSTOS_M2!$H$5:$H$67,0),_xlpm.mat_m2,INDEX(IF(F32="HUANACAXTLE",COSTOS_M2!$D$5:$D$67,IF(F32="ENCINO",COSTOS_M2!$E$5:$E$67,COSTOS_M2!$F$5:$F$67)),_xlpm.fila),_xlpm.cons_m2,INDEX(COSTOS_M2!$G$5:$G$67,_xlpm.fila),_xlpm.prof_factor,IF(AND(E32<>"—",E32<>"",ISNUMBER(E32)),POWER(E32/40,1.8),1),_xlpm.total_m2,(_xlpm.mat_m2+_xlpm.cons_m2)*H32*_xlpm.prof_factor*IF(C32>70,COSTOS_M2!$B$70,1)*IF(D32>244,COSTOS_M2!$B$71,1),_xlpm.total_m2)),"") -> 1571.3913 | J32: =IFERROR(IF(B32="","",INDEX(MANO_DE_OBRA!$P$10:$P$72,MATCH(B32&"|"&IF(H32<=0.5,"CHICO",IF(H32<=1,"MEDIANO","GRANDE")),MANO_DE_OBRA!$Q$10:$Q$72,0))),"") -> 725.196 | K32: =IFERROR(IF(B32="","",_xlfn.LET(_xlpm.clave_prof,B32&"|"&E32,_xlpm.clave_todas,B32&"|TODAS",_xlpm.herr_prof,SUMIFS(HERRAJES!$H$5:$H$36,HERRAJES!$J$5:$J$36,_xlpm.clave_prof),_xlpm.herr_todas,SUMIFS(HERRAJES!$H$5:$H$36,HERRAJES!$J$5:$J$36,_xlpm.clave_todas),IF(_xlpm.herr_prof>0,_xlpm.herr_prof,_xlpm.herr_todas))),"") -> 0 | L32: =IFERROR(IF(B32="","",IF(I32="",0,I32)+IF(J32="",0,J32)+IF(K32="",0,K32)),"") -> 2296.5873 | M32: =IFERROR(IF(L32="","",L32*$D$8),"") -> 2870.7341 | N32: =IFERROR(IF(M32="","",CEILING(M32,50)),"") -> 2900 | O32: 0 | P32: =IFERROR(IF(G32="","",G32*N32*(1-O32)),"") -> 2900
A33: V2 | B33: ZAPATERA EXTRAÍBLE | C33: 94 | D33: 55 | E33: 55 | F33: NOGAL | G33: 4 | H33: =IFERROR(IF(B33="","",(C33/100)*(D33/100)),"") -> 0.517 | I33: =IFERROR(IF(B33="","",_xlfn.LET(_xlpm.tamano,IF(H33<=0.5,"CHICO",IF(H33<=1,"MEDIANO","GRANDE")),_xlpm.clave,B33&"|"&_xlpm.tamano,_xlpm.fila,MATCH(_xlpm.clave,COSTOS_M2!$H$5:$H$67,0),_xlpm.mat_m2,INDEX(IF(F33="HUANACAXTLE",COSTOS_M2!$D$5:$D$67,IF(F33="ENCINO",COSTOS_M2!$E$5:$E$67,COSTOS_M2!$F$5:$F$67)),_xlpm.fila),_xlpm.cons_m2,INDEX(COSTOS_M2!$G$5:$G$67,_xlpm.fila),_xlpm.prof_factor,IF(AND(E33<>"—",E33<>"",ISNUMBER(E33)),POWER(E33/40,1.8),1),_xlpm.total_m2,(_xlpm.mat_m2+_xlpm.cons_m2)*H33*_xlpm.prof_factor*IF(C33>70,COSTOS_M2!$B$70,1)*IF(D33>244,COSTOS_M2!$B$71,1),_xlpm.total_m2)),"") -> 693.90775 | J33: =IFERROR(IF(B33="","",INDEX(MANO_DE_OBRA!$P$10:$P$72,MATCH(B33&"|"&IF(H33<=0.5,"CHICO",IF(H33<=1,"MEDIANO","GRANDE")),MANO_DE_OBRA!$Q$10:$Q$72,0))),"") -> 410.25956 | K33: =IFERROR(IF(B33="","",_xlfn.LET(_xlpm.clave_prof,B33&"|"&E33,_xlpm.clave_todas,B33&"|TODAS",_xlpm.herr_prof,SUMIFS(HERRAJES!$H$5:$H$36,HERRAJES!$J$5:$J$36,_xlpm.clave_prof),_xlpm.herr_todas,SUMIFS(HERRAJES!$H$5:$H$36,HERRAJES!$J$5:$J$36,_xlpm.clave_todas),IF(_xlpm.herr_prof>0,_xlpm.herr_prof,_xlpm.herr_todas))),"") -> 50.52 | L33: =IFERROR(IF(B33="","",IF(I33="",0,I33)+IF(J33="",0,J33)+IF(K33="",0,K33)),"") -> 1154.6873 | M33: =IFERROR(IF(L33="","",L33*$D$8),"") -> 1443.3591 | N33: =IFERROR(IF(M33="","",CEILING(M33,50)),"") -> 1450 | O33: 0 | P33: =IFERROR(IF(G33="","",G33*N33*(1-O33)),"") -> 5800
A34: V2 | B34: ENTREPAÑO DELGADO | C34: 55 | D34: 94 | E34: — | F34: NOGAL | G34: 2 | H34: =IFERROR(IF(B34="","",(C34/100)*(D34/100)),"") -> 0.517 | I34: =IFERROR(IF(B34="","",_xlfn.LET(_xlpm.tamano,IF(H34<=0.5,"CHICO",IF(H34<=1,"MEDIANO","GRANDE")),_xlpm.clave,B34&"|"&_xlpm.tamano,_xlpm.fila,MATCH(_xlpm.clave,COSTOS_M2!$H$5:$H$67,0),_xlpm.mat_m2,INDEX(IF(F34="HUANACAXTLE",COSTOS_M2!$D$5:$D$67,IF(F34="ENCINO",COSTOS_M2!$E$5:$E$67,COSTOS_M2!$F$5:$F$67)),_xlpm.fila),_xlpm.cons_m2,INDEX(COSTOS_M2!$G$5:$G$67,_xlpm.fila),_xlpm.prof_factor,IF(AND(E34<>"—",E34<>"",ISNUMBER(E34)),POWER(E34/40,1.8),1),_xlpm.total_m2,(_xlpm.mat_m2+_xlpm.cons_m2)*H34*_xlpm.prof_factor*IF(C34>70,COSTOS_M2!$B$70,1)*IF(D34>244,COSTOS_M2!$B$71,1),_xlpm.total_m2)),"") -> 405.845 | J34: =IFERROR(IF(B34="","",INDEX(MANO_DE_OBRA!$P$10:$P$72,MATCH(B34&"|"&IF(H34<=0.5,"CHICO",IF(H34<=1,"MEDIANO","GRANDE")),MANO_DE_OBRA!$Q$10:$Q$72,0))),"") -> 400.5588 | K34: =IFERROR(IF(B34="","",_xlfn.LET(_xlpm.clave_prof,B34&"|"&E34,_xlpm.clave_todas,B34&"|TODAS",_xlpm.herr_prof,SUMIFS(HERRAJES!$H$5:$H$36,HERRAJES!$J$5:$J$36,_xlpm.clave_prof),_xlpm.herr_todas,SUMIFS(HERRAJES!$H$5:$H$36,HERRAJES!$J$5:$J$36,_xlpm.clave_todas),IF(_xlpm.herr_prof>0,_xlpm.herr_prof,_xlpm.herr_todas))),"") -> 0 | L34: =IFERROR(IF(B34="","",IF(I34="",0,I34)+IF(J34="",0,J34)+IF(K34="",0,K34)),"") -> 806.4038 | M34: =IFERROR(IF(L34="","",L34*$D$8),"") -> 1008.0048 | N34: =IFERROR(IF(M34="","",CEILING(M34,50)),"") -> 1050 | O34: 0 | P34: =IFERROR(IF(G34="","",G34*N34*(1-O34)),"") -> 2100
A35: V2 | B35: TUBO COLGAR | C35: ESPECIAL | D35: 94 | E35: — | F35: NOGAL | G35: 4 | H35: =IFERROR(IF(B35="","",(C35/100)*(D35/100)),"") | I35: =IFERROR(IF(B35="","",_xlfn.LET(_xlpm.tamano,IF(H35<=0.5,"CHICO",IF(H35<=1,"MEDIANO","GRANDE")),_xlpm.clave,B35&"|"&_xlpm.tamano,_xlpm.fila,MATCH(_xlpm.clave,COSTOS_M2!$H$5:$H$67,0),_xlpm.mat_m2,INDEX(IF(F35="HUANACAXTLE",COSTOS_M2!$D$5:$D$67,IF(F35="ENCINO",COSTOS_M2!$E$5:$E$67,COSTOS_M2!$F$5:$F$67)),_xlpm.fila),_xlpm.cons_m2,INDEX(COSTOS_M2!$G$5:$G$67,_xlpm.fila),_xlpm.prof_factor,IF(AND(E35<>"—",E35<>"",ISNUMBER(E35)),POWER(E35/40,1.8),1),_xlpm.total_m2,(_xlpm.mat_m2+_xlpm.cons_m2)*H35*_xlpm.prof_factor*IF(C35>70,COSTOS_M2!$B$70,1)*IF(D35>244,COSTOS_M2!$B$71,1),_xlpm.total_m2)),"") | J35: =IFERROR(IF(B35="","",INDEX(MANO_DE_OBRA!$P$10:$P$72,MATCH(B35&"|"&IF(H35<=0.5,"CHICO",IF(H35<=1,"MEDIANO","GRANDE")),MANO_DE_OBRA!$Q$10:$Q$72,0))),"") -> 25.593 | K35: =IFERROR(IF(B35="","",_xlfn.LET(_xlpm.clave_prof,B35&"|"&E35,_xlpm.clave_todas,B35&"|TODAS",_xlpm.herr_prof,SUMIFS(HERRAJES!$H$5:$H$36,HERRAJES!$J$5:$J$36,_xlpm.clave_prof),_xlpm.herr_todas,SUMIFS(HERRAJES!$H$5:$H$36,HERRAJES!$J$5:$J$36,_xlpm.clave_todas),IF(_xlpm.herr_prof>0,_xlpm.herr_prof,_xlpm.herr_todas))),"") -> 2.74 | L35: =IFERROR(IF(B35="","",IF(I35="",0,I35)+IF(J35="",0,J35)+IF(K35="",0,K35)),"") -> 28.333 | M35: =IFERROR(IF(L35="","",L35*$D$8),"") -> 35.41625 | N35: =IFERROR(IF(M35="","",CEILING(M35,50)),"") -> 50 | O35: 0 | P35: =IFERROR(IF(G35="","",G35*N35*(1-O35)),"") -> 200
